<?xml version="1.0" encoding="utf-8"?>
<!-- =================================================================================== -->
<!-- |    This document was autogenerated by xacro from /opt/ros/melodic/share/anymal_bear/urdf/anymal.urdf.xacro | -->
<!-- |    EDITING THIS FILE BY HAND IS NOT RECOMMENDED                                 | -->
<!-- =================================================================================== -->
<!-- This file contains the description of the ANYmal Bear robot. -->
<robot name="anymal">
  <material name="black">
    <color rgba="0.0 0.0 0.0 1.0"/>
  </material>
  <material name="blue">
    <color rgba="0.0 0.0 0.8 1.0"/>
  </material>
  <material name="green">
    <color rgba="0.0 0.8 0.0 1.0"/>
  </material>
  <material name="grey">
    <color rgba="0.2 0.2 0.2 1.0"/>
  </material>
  <material name="light_grey">
    <color rgba="0.4 0.4 0.4 1.0"/>
  </material>
  <material name="orange">
    <color rgba="1.0 0.423529411765 0.0392156862745 1.0"/>
  </material>
  <material name="brown">
    <color rgba="0.870588235294 0.811764705882 0.764705882353 1.0"/>
  </material>
  <material name="red">
    <color rgba="0.8 0.0 0.0 1.0"/>
  </material>
  <material name="white">
    <color rgba="1.0 1.0 1.0 1.0"/>
  </material>
  <gazebo>
    <plugin filename="libanymal_gazebo.so" name="gazebo_ros_control">
      <robotNamespace>anymal</robotNamespace>
      <!-- Currently unused -->
      <robotDescription>anymal_description</robotDescription>
      <robotBaseLink>base</robotBaseLink>
    </plugin>
  </gazebo>
  <!-- Material for the visual primitives -->
  <material name="anymal_material">
    <color rgba="0.7 0.7 0.7 1.0"/>
  </material>
  <!-- Xacro:Properties -->
  <!-- [m] -->
  <!-- Base link -->
  <link name="base">
    <visual>
      <origin rpy="0 0 0" xyz="0 0 0"/>
      <geometry>
        <mesh filename="package://anymal_description/urdf/base/2_0_b/anymal_base.dae" scale="0.001 0.001     0.001"/>
      </geometry>
      <material name="anymal_material"/>
    </visual>
    <collision>
      <!-- Main Body -->
      <origin rpy="0 0 0" xyz="0 0 0.08"/>
      <geometry>
        <box size="0.531 0.27 0.24"/>
      </geometry>
    </collision>
    <collision>
      <!-- HAA actuators -->
      <origin rpy="0 1.57079632679 0" xyz="0.227 0.116 0"/>
      <geometry>
        <cylinder length="0.1" radius="0.05"/>
      </geometry>
    </collision>
    <collision>
      <origin rpy="0 1.57079632679 0" xyz="0.227 -0.116 0"/>
      <geometry>
        <cylinder length="0.1" radius="0.05"/>
      </geometry>
    </collision>
    <collision>
      <origin rpy="0 1.57079632679 0" xyz="-0.227 0.116 0"/>
      <geometry>
        <cylinder length="0.1" radius="0.05"/>
      </geometry>
    </collision>
    <collision>
      <origin rpy="0 1.57079632679 0" xyz="-0.227 -0.116 0"/>
      <geometry>
        <cylinder length="0.1" radius="0.05"/>
      </geometry>
    </collision>
    <collision>
      <!-- Belly plate front bump -->
      <origin rpy="0 0 0" xyz="0.2155 0.0 -0.09"/>
      <geometry>
        <box size="0.1 0.1 0.07"/>
      </geometry>
    </collision>
    <collision>
      <!-- Belly plate hind bump-->
      <origin rpy="0 0 0" xyz="-0.2155 0.0 -0.09"/>
      <geometry>
        <box size="0.1 0.1 0.07"/>
      </geometry>
    </collision>
    <collision>
      <!-- Belly plate middle bump-->
      <origin rpy="0 0 0" xyz="0 0 -0.09"/>
      <geometry>
        <box size="0.531 0.02 0.07"/>
      </geometry>
    </collision>
    <collision>
      <!-- Front Mount-->
      <origin rpy="0 0 0" xyz="0.2455 0 0.245"/>
      <geometry>
        <box size="0.02 0.27 0.09"/>
      </geometry>
    </collision>
    <collision>
      <!-- Rear Mount-->
      <origin rpy="0 0 0" xyz="-0.2455 0 0.245"/>
      <geometry>
        <box size="0.02 0.27 0.09"/>
      </geometry>
    </collision>
    <!-- Shell self filtering -->
    <self_filter>
      <origin rpy="0 0 0" xyz="0 0 0.15"/>
      <geometry>
        <box size="0.86 0.4 0.28"/>
      </geometry>
    </self_filter>
  </link>
  <!-- Fixed joint to add dummy inertia link -->
  <joint name="base_to_base_inertia" type="fixed">
    <parent link="base"/>
    <child link="base_inertia"/>
    <origin rpy="0 0 0" xyz="0 0 0"/>
  </joint>
  <!-- Dummy inertia link, because KDL cannot have inertia on the base link -->
  <link name="base_inertia">
    <inertial>
      <origin rpy="0 0 0" xyz="-0.001960558279 -0.001413217745 0.050207125344"/>
      <mass value="16.793507758"/>
      <inertia ixx="0.217391101503" ixy="-0.00132873239126" ixz="-0.00228200226173" iyy="0.639432546734" iyz="-0.00138078263145" izz="0.62414077654"/>
    </inertial>
  </link>
  <!-- Xacro:Properties -->
  <!-- [kg * m^2] -->
  <!-- [A] -->
  <link name="LF_HIP">
    <visual>
      <origin rpy="0 0 0.0" xyz="0 0 0"/>
      <geometry>
        <mesh filename="package://anymal_description/urdf/hip/3_0/anymal_hip_l.dae" scale="0.001 0.001     0.001"/>
      </geometry>
      <material name="anymal_material"/>
    </visual>
    <collision>
      <!-- Protector -->
      <origin rpy="1.57079632679 0 0" xyz="0.0635 -0.009 0.0"/>
      <geometry>
        <cylinder length="0.1" radius="0.08"/>
      </geometry>
    </collision>
    <collision>
      <!-- Heatfins -->
      <origin rpy="1.57079632679 0 0" xyz="0.0635 -0.074 0.0"/>
      <geometry>
        <cylinder length="0.03" radius="0.045"/>
      </geometry>
    </collision>
    <inertial>
      <origin rpy="0 0 0" xyz="0.064516258147 -0.003787101702 -0.000152184388"/>
      <mass value="1.42462064"/>
      <inertia ixx="0.00243023349564" ixy="-1.53023971e-05" ixz="-2.1819095354e-05" iyy="0.00230257239103" iyz="2.6473021273e-05" izz="0.0019806759227"/>
    </inertial>
  </link>
  <!-- Hip joint -->
  <joint name="LF_HAA" type="revolute">
    <parent link="base"/>
    <child link="LF_HIP"/>
    <origin xyz="0.277 0.116 0.0"/>
    <axis xyz="1 0 0"/>
    <limit command_effort="40" current="10" effort="80" gear_velocity="10" lower="-9.42" upper="9.42" velocity="15"/>
    <dynamics damping="0.0" friction="0.0"/>
  </joint>
  <!-- Xacro:Properties -->
  <!-- [m] -->
  <!-- [A] -->
  <link name="LF_THIGH">
    <visual>
      <origin rpy="0 0 0.0" xyz="0 0 0"/>
      <geometry>
        <mesh filename="package://anymal_description/urdf/thigh/3_0/anymal_thigh_l.dae" scale="0.001 0.001     0.001"/>
      </geometry>
      <material name="anymal_material"/>
    </visual>
    <collision>
      <!-- thigh with heat fins -->
      <origin rpy="0.145 0 0" xyz="0 0.035 -0.125"/>
      <geometry>
        <box size="0.08 0.04 0.25"/>
      </geometry>
    </collision>
    <collision>
      <!-- KFE actuator -->
      <origin rpy="1.57079632679 0 0" xyz="0.0 0.069 -0.25"/>
      <geometry>
        <cylinder length="0.12" radius="0.06"/>
      </geometry>
    </collision>
    <collision>
      <!-- upper protector -->
      <origin rpy="1.71579632679 0 0" xyz="0 -0.005 0"/>
      <geometry>
        <cylinder length="0.12" radius="0.066"/>
      </geometry>
    </collision>
    <inertial>
      <origin rpy="0 0 0" xyz="-0.003897968082 0.054226618537 -0.214583373795"/>
      <mass value="1.634976467"/>
      <inertia ixx="0.0120367944369" ixy="6.762065206e-05" ixz="0.000287806340448" iyy="0.0120643637939" iyz="-0.00140610131218" izz="0.00249422574881"/>
    </inertial>
  </link>
  <!-- Thigh joint -->
  <joint name="LF_HFE" type="revolute">
    <parent link="LF_HIP"/>
    <child link="LF_THIGH"/>
    <origin xyz="0.0635                    0.041                    0.0"/>
    <axis xyz="0 1 0"/>
    <limit command_effort="40" current="10" effort="80" gear_velocity="10" lower="-9.42" upper="9.42" velocity="15.0"/>
    <dynamics damping="0.0" friction="0.0"/>
  </joint>
  <!-- Xacro:Properties -->
  <!-- [m] -->
  <!-- [A] -->
  <link name="LF_SHANK">
    <visual>
      <origin rpy="0 0 0.0" xyz="0 0 0"/>
      <geometry>
        <mesh filename="package://anymal_description/urdf/shank/3_0/anymal_shank_l.dae" scale="0.001 0.001     0.001"/>
      </geometry>
      <material name="anymal_material"/>
    </visual>
    <collision>
      <origin rpy="0 1.57079632679 0" xyz="0.065 -0.015 0.01"/>
      <geometry>
        <box size="0.08 0.07 0.13"/>
      </geometry>
    </collision>
    <inertial>
      <origin rpy="0 0 0" xyz="0.030816858139 -0.004617229294 0.000893125713"/>
      <mass value="0.207204302"/>
      <inertia ixx="0.0002104880248" ixy="-5.6750980345e-05" ixz="1.0127699391e-05" iyy="0.000676270210023" iyz="-8.22869024e-07" izz="0.000545032674924"/>
    </inertial>
  </link>
  <!-- Shank joint -->
  <joint name="LF_KFE" type="revolute">
    <parent link="LF_THIGH"/>
    <child link="LF_SHANK"/>
    <origin xyz="0.0 0.109 -0.25"/>
    <axis xyz="0 1 0"/>
    <limit command_effort="40" current="10" effort="80" gear_velocity="10" lower="-9.42" upper="9.42" velocity="15.0"/>
    <dynamics damping="0.0" friction="0.0"/>
  </joint>
  <!-- Xacro:Properties -->
  <!-- [m] -->
  <!-- Shank to Adapter joint -->
  <joint name="LF_SHANK_TO_ADAPTER" type="fixed">
    <parent link="LF_SHANK"/>
    <child link="LF_ADAPTER"/>
    <origin rpy="0.0 0.0 0.0" xyz="0.1 -0.02 0.0"/>
  </joint>
  <!-- Adapter link -->
  <link name="LF_ADAPTER">
    <visual>
      <origin rpy="0 0 0.0" xyz="0 0 0.032"/>
      <geometry>
        <mesh filename="package://anymal_b/urdf/foot/12_0/anymal_foot.dae" scale="0.001 0.001     0.001"/>
      </geometry>
      <material name="anymal_material"/>
    </visual>
    <collision>
      <origin rpy="0 0 0" xyz="0 0 -0.160625"/>
      <geometry>
        <cylinder length="0.32125" radius="0.015"/>
      </geometry>
      <material name="anymal_material"/>
    </collision>
    <inertial>
      <origin rpy="0 0 0" xyz="-8.66e-10 -1.472e-09 -0.244345749188"/>
      <mass value="0.140170767"/>
      <inertia ixx="0.00159938741862" ixy="-9.32e-13" ixz="1.039e-11" iyy="0.00159938741932" iyz="1.7563e-11" izz="5.4423177329e-05"/>
    </inertial>
  </link>
  <!-- Adapter to Foot joint -->
  <joint name="LF_ADAPTER_TO_FOOT" type="fixed">
    <parent link="LF_ADAPTER"/>
    <child link="LF_FOOT"/>
    <origin rpy="0.0 0.0 0.0" xyz="0.0 0.0 -0.32125"/>
  </joint>
  <!-- Foot link -->
  <link name="LF_FOOT">
    <collision>
      <origin xyz="0 0 0.02325"/>
      <geometry>
        <sphere radius="0.031"/>
      </geometry>
    </collision>
  </link>
  <!-- Gazebo customization -->
  <gazebo reference="LF_FOOT">
    <kp>1000000.0</kp>
    <kd>100.0</kd>
    <mu1>0.8</mu1>
    <mu2>0.8</mu2>
  </gazebo>
  <!-- Xacro:Properties -->
  <!-- [kg * m^2] -->
  <!-- [A] -->
  <link name="RF_HIP">
    <visual>
      <origin rpy="0 0 0.0" xyz="0 0 0"/>
      <geometry>
        <mesh filename="package://anymal_description/urdf/hip/3_0/anymal_hip_r.dae" scale="0.001 0.001     0.001"/>
      </geometry>
      <material name="anymal_material"/>
    </visual>
    <collision>
      <!-- Protector -->
      <origin rpy="1.57079632679 0 0" xyz="0.0635 0.009 0.0"/>
      <geometry>
        <cylinder length="0.1" radius="0.08"/>
      </geometry>
    </collision>
    <collision>
      <!-- Heatfins -->
      <origin rpy="1.57079632679 0 0" xyz="0.0635 0.074 0.0"/>
      <geometry>
        <cylinder length="0.03" radius="0.045"/>
      </geometry>
    </collision>
    <inertial>
      <origin rpy="0 0 0" xyz="0.064516258147 0.003787101702 -0.000152184388"/>
      <mass value="1.42462064"/>
      <inertia ixx="0.00243023349564" ixy="1.53023971e-05" ixz="-2.1819095354e-05" iyy="0.00230257239103" iyz="-2.6473021273e-05" izz="0.0019806759227"/>
    </inertial>
  </link>
  <!-- Hip joint -->
  <joint name="RF_HAA" type="revolute">
    <parent link="base"/>
    <child link="RF_HIP"/>
    <origin xyz="0.277 -0.116 0.0"/>
    <axis xyz="1 0 0"/>
    <limit command_effort="40" current="10" effort="80" gear_velocity="10" lower="-9.42" upper="9.42" velocity="15"/>
    <dynamics damping="0.0" friction="0.0"/>
  </joint>
  <!-- Xacro:Properties -->
  <!-- [m] -->
  <!-- [A] -->
  <link name="RF_THIGH">
    <visual>
      <origin rpy="0 0 0.0" xyz="0 0 0"/>
      <geometry>
        <mesh filename="package://anymal_description/urdf/thigh/3_0/anymal_thigh_r.dae" scale="0.001 0.001     0.001"/>
      </geometry>
      <material name="anymal_material"/>
    </visual>
    <collision>
      <!-- thigh with heat fins -->
      <origin rpy="-0.145 0 0" xyz="0 -0.035 -0.125"/>
      <geometry>
        <box size="0.08 0.04 0.25"/>
      </geometry>
    </collision>
    <collision>
      <!-- KFE actuator -->
      <origin rpy="1.57079632679 0 0" xyz="0.0 -0.069 -0.25"/>
      <geometry>
        <cylinder length="0.12" radius="0.06"/>
      </geometry>
    </collision>
    <collision>
      <!-- upper protector -->
      <origin rpy="-1.71579632679 0 0" xyz="0 0.005 0"/>
      <geometry>
        <cylinder length="0.12" radius="0.066"/>
      </geometry>
    </collision>
    <inertial>
      <origin rpy="0 0 0" xyz="-0.003897968082 -0.054226618537 -0.214583373795"/>
      <mass value="1.634976467"/>
      <inertia ixx="0.0120367944369" ixy="-6.762065206e-05" ixz="0.000287806340448" iyy="0.0120643637939" iyz="0.00140610131218" izz="0.00249422574881"/>
    </inertial>
  </link>
  <!-- Thigh joint -->
  <joint name="RF_HFE" type="revolute">
    <parent link="RF_HIP"/>
    <child link="RF_THIGH"/>
    <origin xyz="0.0635                    -0.041                    0.0"/>
    <axis xyz="0 1 0"/>
    <limit command_effort="40" current="10" effort="80" gear_velocity="10" lower="-9.42" upper="9.42" velocity="15.0"/>
    <dynamics damping="0.0" friction="0.0"/>
  </joint>
  <!-- Xacro:Properties -->
  <!-- [m] -->
  <!-- [A] -->
  <link name="RF_SHANK">
    <visual>
      <origin rpy="0 0 0.0" xyz="0 0 0"/>
      <geometry>
        <mesh filename="package://anymal_description/urdf/shank/3_0/anymal_shank_r.dae" scale="0.001 0.001     0.001"/>
      </geometry>
      <material name="anymal_material"/>
    </visual>
    <collision>
      <origin rpy="0 1.57079632679 0" xyz="0.065 0.015 0.01"/>
      <geometry>
        <box size="0.08 0.07 0.13"/>
      </geometry>
    </collision>
    <inertial>
      <origin rpy="0 0 0" xyz="0.030816858139 0.004617229294 0.000893125713"/>
      <mass value="0.207204302"/>
      <inertia ixx="0.0002104880248" ixy="5.6750980345e-05" ixz="1.0127699391e-05" iyy="0.000676270210023" iyz="8.22869024e-07" izz="0.000545032674924"/>
    </inertial>
  </link>
  <!-- Shank joint -->
  <joint name="RF_KFE" type="revolute">
    <parent link="RF_THIGH"/>
    <child link="RF_SHANK"/>
    <origin xyz="0.0 -0.109 -0.25"/>
    <axis xyz="0 1 0"/>
    <limit command_effort="40" current="10" effort="80" gear_velocity="10" lower="-9.42" upper="9.42" velocity="15.0"/>
    <dynamics damping="0.0" friction="0.0"/>
  </joint>
  <!-- Xacro:Properties -->
  <!-- [m] -->
  <!-- Shank to Adapter joint -->
  <joint name="RF_SHANK_TO_ADAPTER" type="fixed">
    <parent link="RF_SHANK"/>
    <child link="RF_ADAPTER"/>
    <origin rpy="-0.0 0.0 -0.0" xyz="0.1 0.02 0.0"/>
  </joint>
  <!-- Adapter link -->
  <link name="RF_ADAPTER">
    <visual>
      <origin rpy="0 0 0.0" xyz="0 0 0.032"/>
      <geometry>
        <mesh filename="package://anymal_b/urdf/foot/12_0/anymal_foot.dae" scale="0.001 0.001     0.001"/>
      </geometry>
      <material name="anymal_material"/>
    </visual>
    <collision>
      <origin rpy="0 0 0" xyz="0 0 -0.160625"/>
      <geometry>
        <cylinder length="0.32125" radius="0.015"/>
      </geometry>
      <material name="anymal_material"/>
    </collision>
    <inertial>
      <origin rpy="0 0 0" xyz="-8.66e-10 -1.472e-09 -0.244345749188"/>
      <mass value="0.140170767"/>
      <inertia ixx="0.00159938741862" ixy="-9.32e-13" ixz="1.039e-11" iyy="0.00159938741932" iyz="1.7563e-11" izz="5.4423177329e-05"/>
    </inertial>
  </link>
  <!-- Adapter to Foot joint -->
  <joint name="RF_ADAPTER_TO_FOOT" type="fixed">
    <parent link="RF_ADAPTER"/>
    <child link="RF_FOOT"/>
    <origin rpy="-0.0 0.0 -0.0" xyz="0.0 -0.0 -0.32125"/>
  </joint>
  <!-- Foot link -->
  <link name="RF_FOOT">
    <collision>
      <origin xyz="0 0 0.02325"/>
      <geometry>
        <sphere radius="0.031"/>
      </geometry>
    </collision>
  </link>
  <!-- Gazebo customization -->
  <gazebo reference="RF_FOOT">
    <kp>1000000.0</kp>
    <kd>100.0</kd>
    <mu1>0.8</mu1>
    <mu2>0.8</mu2>
  </gazebo>
  <!-- Xacro:Properties -->
  <!-- [kg * m^2] -->
  <!-- [A] -->
  <link name="LH_HIP">
    <visual>
      <origin rpy="0 0 -3.14159265359" xyz="0 0 0"/>
      <geometry>
        <mesh filename="package://anymal_description/urdf/hip/3_0/anymal_hip_r.dae" scale="0.001 0.001     0.001"/>
      </geometry>
      <material name="anymal_material"/>
    </visual>
    <collision>
      <!-- Protector -->
      <origin rpy="-1.57079632679 0 0" xyz="-0.0635 -0.009 0.0"/>
      <geometry>
        <cylinder length="0.1" radius="0.08"/>
      </geometry>
    </collision>
    <collision>
      <!-- Heatfins -->
      <origin rpy="-1.57079632679 0 0" xyz="-0.0635 -0.074 0.0"/>
      <geometry>
        <cylinder length="0.03" radius="0.045"/>
      </geometry>
    </collision>
    <inertial>
      <origin rpy="0 0 0" xyz="-0.064516258147 -0.003787101702 -0.000152184388"/>
      <mass value="1.42462064"/>
      <inertia ixx="0.00243023349564" ixy="1.53023971e-05" ixz="2.1819095354e-05" iyy="0.00230257239103" iyz="2.6473021273e-05" izz="0.0019806759227"/>
    </inertial>
  </link>
  <!-- Hip joint -->
  <joint name="LH_HAA" type="revolute">
    <parent link="base"/>
    <child link="LH_HIP"/>
    <origin xyz="-0.277 0.116 0.0"/>
    <axis xyz="1 0 0"/>
    <limit command_effort="40" current="10" effort="80" gear_velocity="10" lower="-9.42" upper="9.42" velocity="15"/>
    <dynamics damping="0.0" friction="0.0"/>
  </joint>
  <!-- Xacro:Properties -->
  <!-- [m] -->
  <!-- [A] -->
  <link name="LH_THIGH">
    <visual>
      <origin rpy="0 0 -3.14159265359" xyz="0 0 0"/>
      <geometry>
        <mesh filename="package://anymal_description/urdf/thigh/3_0/anymal_thigh_r.dae" scale="0.001 0.001     0.001"/>
      </geometry>
      <material name="anymal_material"/>
    </visual>
    <collision>
      <!-- thigh with heat fins -->
      <origin rpy="0.145 0 0" xyz="0 0.035 -0.125"/>
      <geometry>
        <box size="0.08 0.04 0.25"/>
      </geometry>
    </collision>
    <collision>
      <!-- KFE actuator -->
      <origin rpy="1.57079632679 0 0" xyz="0.0 0.069 -0.25"/>
      <geometry>
        <cylinder length="0.12" radius="0.06"/>
      </geometry>
    </collision>
    <collision>
      <!-- upper protector -->
      <origin rpy="1.71579632679 0 0" xyz="0 -0.005 0"/>
      <geometry>
        <cylinder length="0.12" radius="0.066"/>
      </geometry>
    </collision>
    <inertial>
      <origin rpy="0 0 0" xyz="0.003897968082 0.054226618537 -0.214583373795"/>
      <mass value="1.634976467"/>
      <inertia ixx="0.0120367944369" ixy="-6.762065206e-05" ixz="-0.000287806340448" iyy="0.0120643637939" iyz="-0.00140610131218" izz="0.00249422574881"/>
    </inertial>
  </link>
  <!-- Thigh joint -->
  <joint name="LH_HFE" type="revolute">
    <parent link="LH_HIP"/>
    <child link="LH_THIGH"/>
    <origin xyz="-0.0635                    0.041                    0.0"/>
    <axis xyz="0 1 0"/>
    <limit command_effort="40" current="10" effort="80" gear_velocity="10" lower="-9.42" upper="9.42" velocity="15.0"/>
    <dynamics damping="0.0" friction="0.0"/>
  </joint>
  <!-- Xacro:Properties -->
  <!-- [m] -->
  <!-- [A] -->
  <link name="LH_SHANK">
    <visual>
      <origin rpy="0 0 -3.14159265359" xyz="0 0 0"/>
      <geometry>
        <mesh filename="package://anymal_description/urdf/shank/3_0/anymal_shank_r.dae" scale="0.001 0.001     0.001"/>
      </geometry>
      <material name="anymal_material"/>
    </visual>
    <collision>
      <origin rpy="0 1.57079632679 0" xyz="-0.065 -0.015 0.01"/>
      <geometry>
        <box size="0.08 0.07 0.13"/>
      </geometry>
    </collision>
    <inertial>
      <origin rpy="0 0 0" xyz="-0.030816858139 -0.004617229294 0.000893125713"/>
      <mass value="0.207204302"/>
      <inertia ixx="0.0002104880248" ixy="5.6750980345e-05" ixz="-1.0127699391e-05" iyy="0.000676270210023" iyz="-8.22869024e-07" izz="0.000545032674924"/>
    </inertial>
  </link>
  <!-- Shank joint -->
  <joint name="LH_KFE" type="revolute">
    <parent link="LH_THIGH"/>
    <child link="LH_SHANK"/>
    <origin xyz="-0.0 0.109 -0.25"/>
    <axis xyz="0 1 0"/>
    <limit command_effort="40" current="10" effort="80" gear_velocity="10" lower="-9.42" upper="9.42" velocity="15.0"/>
    <dynamics damping="0.0" friction="0.0"/>
  </joint>
  <!-- Xacro:Properties -->
  <!-- [m] -->
  <!-- Shank to Adapter joint -->
  <joint name="LH_SHANK_TO_ADAPTER" type="fixed">
    <parent link="LH_SHANK"/>
    <child link="LH_ADAPTER"/>
    <origin rpy="0.0 -0.0 -0.0" xyz="-0.1 -0.02 0.0"/>
  </joint>
  <!-- Adapter link -->
  <link name="LH_ADAPTER">
    <visual>
      <origin rpy="0 0 -3.14159265359" xyz="0 0 0.032"/>
      <geometry>
        <mesh filename="package://anymal_b/urdf/foot/12_0/anymal_foot.dae" scale="0.001 0.001     0.001"/>
      </geometry>
      <material name="anymal_material"/>
    </visual>
    <collision>
      <origin rpy="0 0 0" xyz="0 0 -0.160625"/>
      <geometry>
        <cylinder length="0.32125" radius="0.015"/>
      </geometry>
      <material name="anymal_material"/>
    </collision>
    <inertial>
      <origin rpy="0 0 0" xyz="-8.66e-10 -1.472e-09 -0.244345749188"/>
      <mass value="0.140170767"/>
      <inertia ixx="0.00159938741862" ixy="-9.32e-13" ixz="1.039e-11" iyy="0.00159938741932" iyz="1.7563e-11" izz="5.4423177329e-05"/>
    </inertial>
  </link>
  <!-- Adapter to Foot joint -->
  <joint name="LH_ADAPTER_TO_FOOT" type="fixed">
    <parent link="LH_ADAPTER"/>
    <child link="LH_FOOT"/>
    <origin rpy="0.0 -0.0 -0.0" xyz="-0.0 0.0 -0.32125"/>
  </joint>
  <!-- Foot link -->
  <link name="LH_FOOT">
    <collision>
      <origin xyz="0 0 0.02325"/>
      <geometry>
        <sphere radius="0.031"/>
      </geometry>
    </collision>
  </link>
  <!-- Gazebo customization -->
  <gazebo reference="LH_FOOT">
    <kp>1000000.0</kp>
    <kd>100.0</kd>
    <mu1>0.8</mu1>
    <mu2>0.8</mu2>
  </gazebo>
  <!-- Xacro:Properties -->
  <!-- [kg * m^2] -->
  <!-- [A] -->
  <link name="RH_HIP">
    <visual>
      <origin rpy="0 0 -3.14159265359" xyz="0 0 0"/>
      <geometry>
        <mesh filename="package://anymal_description/urdf/hip/3_0/anymal_hip_l.dae" scale="0.001 0.001     0.001"/>
      </geometry>
      <material name="anymal_material"/>
    </visual>
    <collision>
      <!-- Protector -->
      <origin rpy="-1.57079632679 0 0" xyz="-0.0635 0.009 0.0"/>
      <geometry>
        <cylinder length="0.1" radius="0.08"/>
      </geometry>
    </collision>
    <collision>
      <!-- Heatfins -->
      <origin rpy="-1.57079632679 0 0" xyz="-0.0635 0.074 0.0"/>
      <geometry>
        <cylinder length="0.03" radius="0.045"/>
      </geometry>
    </collision>
    <inertial>
      <origin rpy="0 0 0" xyz="-0.064516258147 0.003787101702 -0.000152184388"/>
      <mass value="1.42462064"/>
      <inertia ixx="0.00243023349564" ixy="-1.53023971e-05" ixz="2.1819095354e-05" iyy="0.00230257239103" iyz="-2.6473021273e-05" izz="0.0019806759227"/>
    </inertial>
  </link>
  <!-- Hip joint -->
  <joint name="RH_HAA" type="revolute">
    <parent link="base"/>
    <child link="RH_HIP"/>
    <origin xyz="-0.277 -0.116 0.0"/>
    <axis xyz="1 0 0"/>
    <limit command_effort="40" current="10" effort="80" gear_velocity="10" lower="-9.42" upper="9.42" velocity="15"/>
    <dynamics damping="0.0" friction="0.0"/>
  </joint>
  <!-- Xacro:Properties -->
  <!-- [m] -->
  <!-- [A] -->
  <link name="RH_THIGH">
    <visual>
      <origin rpy="0 0 -3.14159265359" xyz="0 0 0"/>
      <geometry>
        <mesh filename="package://anymal_description/urdf/thigh/3_0/anymal_thigh_l.dae" scale="0.001 0.001     0.001"/>
      </geometry>
      <material name="anymal_material"/>
    </visual>
    <collision>
      <!-- thigh with heat fins -->
      <origin rpy="-0.145 0 0" xyz="0 -0.035 -0.125"/>
      <geometry>
        <box size="0.08 0.04 0.25"/>
      </geometry>
    </collision>
    <collision>
      <!-- KFE actuator -->
      <origin rpy="1.57079632679 0 0" xyz="0.0 -0.069 -0.25"/>
      <geometry>
        <cylinder length="0.12" radius="0.06"/>
      </geometry>
    </collision>
    <collision>
      <!-- upper protector -->
      <origin rpy="-1.71579632679 0 0" xyz="0 0.005 0"/>
      <geometry>
        <cylinder length="0.12" radius="0.066"/>
      </geometry>
    </collision>
    <inertial>
      <origin rpy="0 0 0" xyz="0.003897968082 -0.054226618537 -0.214583373795"/>
      <mass value="1.634976467"/>
      <inertia ixx="0.0120367944369" ixy="6.762065206e-05" ixz="-0.000287806340448" iyy="0.0120643637939" iyz="0.00140610131218" izz="0.00249422574881"/>
    </inertial>
  </link>
  <!-- Thigh joint -->
  <joint name="RH_HFE" type="revolute">
    <parent link="RH_HIP"/>
    <child link="RH_THIGH"/>
    <origin xyz="-0.0635                    -0.041                    0.0"/>
    <axis xyz="0 1 0"/>
    <limit command_effort="40" current="10" effort="80" gear_velocity="10" lower="-9.42" upper="9.42" velocity="15.0"/>
    <dynamics damping="0.0" friction="0.0"/>
  </joint>
  <!-- Xacro:Properties -->
  <!-- [m] -->
  <!-- [A] -->
  <link name="RH_SHANK">
    <visual>
      <origin rpy="0 0 -3.14159265359" xyz="0 0 0"/>
      <geometry>
        <mesh filename="package://anymal_description/urdf/shank/3_0/anymal_shank_l.dae" scale="0.001 0.001     0.001"/>
      </geometry>
      <material name="anymal_material"/>
    </visual>
    <collision>
      <origin rpy="0 1.57079632679 0" xyz="-0.065 0.015 0.01"/>
      <geometry>
        <box size="0.08 0.07 0.13"/>
      </geometry>
    </collision>
    <inertial>
      <origin rpy="0 0 0" xyz="-0.030816858139 0.004617229294 0.000893125713"/>
      <mass value="0.207204302"/>
      <inertia ixx="0.0002104880248" ixy="-5.6750980345e-05" ixz="-1.0127699391e-05" iyy="0.000676270210023" iyz="8.22869024e-07" izz="0.000545032674924"/>
    </inertial>
  </link>
  <!-- Shank joint -->
  <joint name="RH_KFE" type="revolute">
    <parent link="RH_THIGH"/>
    <child link="RH_SHANK"/>
    <origin xyz="-0.0 -0.109 -0.25"/>
    <axis xyz="0 1 0"/>
    <limit command_effort="40" current="10" effort="80" gear_velocity="10" lower="-9.42" upper="9.42" velocity="15.0"/>
    <dynamics damping="0.0" friction="0.0"/>
  </joint>
  <!-- Xacro:Properties -->
  <!-- [m] -->
  <!-- Shank to Adapter joint -->
  <joint name="RH_SHANK_TO_ADAPTER" type="fixed">
    <parent link="RH_SHANK"/>
    <child link="RH_ADAPTER"/>
    <origin rpy="-0.0 -0.0 0.0" xyz="-0.1 0.02 0.0"/>
  </joint>
  <!-- Adapter link -->
  <link name="RH_ADAPTER">
    <visual>
      <origin rpy="0 0 -3.14159265359" xyz="0 0 0.032"/>
      <geometry>
        <mesh filename="package://anymal_b/urdf/foot/12_0/anymal_foot.dae" scale="0.001 0.001     0.001"/>
      </geometry>
      <material name="anymal_material"/>
    </visual>
    <collision>
      <origin rpy="0 0 0" xyz="0 0 -0.160625"/>
      <geometry>
        <cylinder length="0.32125" radius="0.015"/>
      </geometry>
      <material name="anymal_material"/>
    </collision>
    <inertial>
      <origin rpy="0 0 0" xyz="-8.66e-10 -1.472e-09 -0.244345749188"/>
      <mass value="0.140170767"/>
      <inertia ixx="0.00159938741862" ixy="-9.32e-13" ixz="1.039e-11" iyy="0.00159938741932" iyz="1.7563e-11" izz="5.4423177329e-05"/>
    </inertial>
  </link>
  <!-- Adapter to Foot joint -->
  <joint name="RH_ADAPTER_TO_FOOT" type="fixed">
    <parent link="RH_ADAPTER"/>
    <child link="RH_FOOT"/>
    <origin rpy="-0.0 -0.0 0.0" xyz="-0.0 -0.0 -0.32125"/>
  </joint>
  <!-- Foot link -->
  <link name="RH_FOOT">
    <collision>
      <origin xyz="0 0 0.02325"/>
      <geometry>
        <sphere radius="0.031"/>
      </geometry>
    </collision>
  </link>
  <!-- Gazebo customization -->
  <gazebo reference="RH_FOOT">
    <kp>1000000.0</kp>
    <kd>100.0</kd>
    <mu1>0.8</mu1>
    <mu2>0.8</mu2>
  </gazebo>
  <link name="imu_link">
    <visual>
      <origin rpy="0 0 0" xyz="0 0 0.011"/>
      <geometry>
        <box size="0.058 0.058 0.022"/>
      </geometry>
      <material name="orange"/>
    </visual>
    <collision>
      <origin rpy="0 0 0" xyz="0 0 0.011"/>
      <geometry>
        <box size="0.058 0.058 0.022"/>
      </geometry>
    </collision>
    <inertial>
      <mass value="0.05"/>
      <origin xyz="0 0 0"/>
      <inertia ixx="1.60333333333e-05" ixy="0.0" ixz="0.0" iyy="2.80333333333e-05" iyz="0.0" izz="1.60333333333e-05"/>
    </inertial>
  </link>
  <joint name="imu_joint" type="fixed">
    <parent link="base"/>
    <child link="imu_link"/>
    <origin rpy="0 3.14159265359 0" xyz="0.038 0.06245 0.1837"/>
  </joint>
  <gazebo reference="imu_link">
    <material>Gazebo/Orange</material>
    <mu1>0.8</mu1>
    <mu2>0.8</mu2>
  </gazebo>
  <gazebo reference="imu_joint">
      </gazebo>
  <gazebo>
    <plugin filename="libany_hector_gazebo_ros_imu.so" name="imu_plugin">
      <robotNamespace>sensors</robotNamespace>
      <bodyName>imu_link</bodyName>
      <frameId>imu_link</frameId>
      <topicName>imu</topicName>
      <biasTopicName>imu/bias</biasTopicName>
      <serviceName>imu/calibrate</serviceName>
      <updateRate>400</updateRate>
    </plugin>
  </gazebo>
  <!-- base to mount joint -->
  <joint name="base_to_lidar_mount" type="fixed">
    <parent link="base"/>
    <child link="lidar_mount"/>
    <origin rpy="0 0 0" xyz="-0.102 0.0 0.2896"/>
  </joint>
  <link name="lidar_mount">
    <visual>
      <origin rpy="0.0 0.0 0.0" xyz="0.0 0.0 0.0"/>
      <geometry>
        <mesh filename="package://anymal_b/urdf/modules/lidar_mount/anymal_velodyne_mount_cage.dae" scale=".001 .001 .001"/>
      </geometry>
    </visual>
    <material name="anymal_material"/>
    <collision>
      <origin rpy="0.0 0.0 0.0" xyz="-0.015 0.0 -0.025"/>
      <geometry>
        <cylinder length="0.15" radius="0.10"/>
      </geometry>
      <material name="anymal_material"/>
    </collision>
    <inertial>
      <!-- Values from CAD -->
      <origin rpy="0.0 0.0 0.0" xyz="-0.003470719564                        -0.000437953244                         0.009296175974"/>
      <mass value="0.468309149"/>
      <inertia ixx="0.002023718043706" ixy="0.000007237377195" ixz="0.000088125050002" iyy="0.001843825349439" iyz="-0.000005839762850" izz="0.002035845574943"/>
    </inertial>
  </link>
  <!-- Mount self filtering -->
  <self_filter>
    <origin rpy="0.0 0.0 0.0" xyz="-0.015 0.0 -0.025"/>
    <geometry>
      <cylinder length="0.17" radius="0.13"/>
    </geometry>
  </self_filter>
  <joint name="lidar_mount_to_lidar_axis_aligned" type="fixed">
    <origin rpy="0.0 0.0 -2.443460953" xyz="0.0 0.0 0.0"/>
    <parent link="lidar_mount"/>
    <child link="lidar_axis_aligned"/>
  </joint>
  <link name="lidar_axis_aligned">
    <!--inertial>
        <mass value="0.590"/>
        <origin xyz="0 0 0.03585"/>
        <inertia ixx="${(0.59 * (3.0*0.0516*0.0516 + 0.0717*0.0717)) / 12.0}" ixy="0" ixz="0"
          iyy="${(0.59 * (3.0*0.0516*0.0516 + 0.0717*0.0717)) / 12.0}" iyz="0"
          izz="${0.5 * 0.59 * (0.0516*0.0516)}"/>
      </inertial-->
    <inertial>
      <mass value="0.589004276"/>
      <origin xyz="-0.000393930511                       0.000465473191                      -0.002216548208"/>
      <inertia ixx="0.000646625073623" ixy="-0.000010230485148" ixz="0.000006639631820" iyy="0.000643015385131" iyz="-0.000007835650222" izz="0.000768918200999"/>
    </inertial>
    <visual>
      <origin rpy="0 0 0" xyz="0 0 -0.0377"/>
      <geometry>
        <mesh filename="package://velodyne_description/meshes/VLP16_base_1.dae"/>
      </geometry>
    </visual>
    <visual>
      <origin rpy="0 0 0" xyz="0 0 -0.0377"/>
      <geometry>
        <mesh filename="package://velodyne_description/meshes/VLP16_base_2.dae"/>
      </geometry>
    </visual>
    <collision>
      <origin rpy="0 0 0" xyz="0 0 0"/>
      <geometry>
        <cylinder length="0.0717" radius="0.0516"/>
      </geometry>
    </collision>
  </link>
  <joint name="lidar_axis_aligned_to_velodyne" type="fixed">
    <origin rpy="0 0 0" xyz="0.0 0.0 0.0"/>
    <parent link="lidar_axis_aligned"/>
    <child link="lidar"/>
  </joint>
  <link name="lidar">
    <inertial>
      <mass value="0.01"/>
      <origin xyz="0 0 0"/>
      <inertia ixx="1e-7" ixy="0" ixz="0" iyy="1e-7" iyz="0" izz="1e-7"/>
    </inertial>
    <visual>
      <origin xyz="0 0 -0.0377"/>
      <geometry>
        <mesh filename="package://velodyne_description/meshes/VLP16_scan.dae"/>
      </geometry>
    </visual>
  </link>
  <!-- Gazebo requires the velodyne_gazebo_plugins package -->
  <gazebo reference="lidar">
    <sensor name="lidar-VLP16" type="ray">
      <pose>0 0 0 0 0 0</pose>
      <visualize>false</visualize>
      <update_rate>10</update_rate>
      <ray>
        <scan>
          <horizontal>
            <samples>440</samples>
            <resolution>1</resolution>
            <min_angle>-3.14159265359</min_angle>
            <max_angle>3.14159265359</max_angle>
          </horizontal>
          <vertical>
            <samples>16</samples>
            <resolution>1</resolution>
            <min_angle>-0.261799387799</min_angle>
            <max_angle> 0.261799387799</max_angle>
          </vertical>
        </scan>
        <range>
          <min>0.3</min>
          <max>131.0</max>
          <resolution>0.001</resolution>
        </range>
        <noise>
          <type>gaussian</type>
          <mean>0.0</mean>
          <stddev>0.0</stddev>
        </noise>
      </ray>
      <plugin filename="libgazebo_ros_velodyne_laser.so" name="gazebo_ros_laser_controller">
        <topicName>/lidar/point_cloud</topicName>
        <frameName>lidar</frameName>
        <min_range>0.9</min_range>
        <max_range>130.0</max_range>
        <gaussianNoise>0.008</gaussianNoise>
      </plugin>
    </sensor>
  </gazebo>
  <!-- Module attachment -->
  <joint name="base_to_handle_mount_front_axis_aligned" type="fixed">
    <parent link="base"/>
    <child link="handle_mount_front"/>
    <origin rpy="0.0 0.0 0.0" xyz="0.2692 0.0 0.1569"/>
  </joint>
  <!-- Mount module axis aligned -->
  <link name="handle_mount_front">
    <visual>
      <origin rpy="0 0 0" xyz="0 0 0"/>
      <geometry>
        <mesh filename="package://anymal_b/urdf/modules/handle_mount/handle_mount_2.dae" scale=".001 .001 .001"/>
      </geometry>
      <material name="anymal_material"/>
    </visual>
    <collision>
      <origin rpy="0 0 0" xyz="0.07 0.0 0.01"/>
      <geometry>
        <box size="0.139 0.152 0.097"/>
      </geometry>
      <material name="anymal_material"/>
    </collision>
    <inertial>
      <origin rpy="0 0 0" xyz="0 0 0"/>
      <mass value="0.001"/>
      <inertia ixx="0.00001" ixy="0.0" ixz="0.0" iyy="0.00001" iyz="0.0" izz="0.00001"/>
    </inertial>
  </link>
  <joint name="handle_mount_front_to_sensor_mount_axis_aligned" type="fixed">
    <parent link="handle_mount_front"/>
    <child link="handle_mount_front_sensor_mount_axis_aligned"/>
    <origin rpy="0 0 0" xyz="0.079 0.0 0.004724"/>
  </joint>
  <link name="handle_mount_front_sensor_mount_axis_aligned"/>
  <!-- Mount calibration joint -->
  <joint name="handle_mount_front_sensor_mount_axis_aligned_to_depth_camera_front_mount" type="fixed">
    <parent link="handle_mount_front_sensor_mount_axis_aligned"/>
    <child link="depth_camera_front_mount"/>
    <origin rpy="0.0 0.0 0.0" xyz="0.0 0.0 0.0"/>
  </joint>
  <!-- Mount link -->
  <link name="depth_camera_front_mount">
    <inertial>
      <origin rpy="0 0 0" xyz="0.054218447194                     -0.000000283793                      0.020065663731"/>
      <mass value="0.243898067"/>
      <inertia ixx="0.000779856566866" ixy="0.000000002160682" ixz="0.000147656791902" iyy="0.000570366165358" iyz="0.000000000478926" izz="0.001154870002255"/>
    </inertial>
  </link>
  <!-- Mount tilting joint -->
  <joint name="depth_camera_front_mount_to_depth_camera_front_mount_tilted" type="fixed">
    <parent link="depth_camera_front_mount"/>
    <child link="depth_camera_front_mount_tilted"/>
    <origin rpy="0.0532019989239 0.614793974344 0.0" xyz="0 0 0"/>
  </joint>
  <!-- zr300 -->
  <!-- Mount tilted link -->
  <link name="depth_camera_front_mount_tilted">
    <visual>
      <origin rpy="0 0 0" xyz="0 0 0"/>
      <geometry>
        <mesh filename="package://anymal_b/urdf/modules/depth_camera_mount/anymal_realsense_mount_d435.dae" scale=".001 .001 .001"/>
      </geometry>
      <material name="anymal_material"/>
    </visual>
    <collision>
      <origin rpy="0.0 0.0 0.0" xyz="0.0145 -0.005 -0.010"/>
      <geometry>
        <box size="0.057 0.120 0.034"/>
      </geometry>
      <material name="anymal_material"/>
    </collision>
    <inertial>
      <origin rpy="0 0 0" xyz="0.013859179019                       -0.000000303238                       -0.005235135645"/>
      <mass value="0.015185133"/>
      <inertia ixx="0.000024367910497" ixy="0.000000000125897" ixz="0.000000298159431" iyy="0.000003910480547" iyz="0.000000000030411" izz="0.000025490557443"/>
    </inertial>
  </link>
  <!-- d435 -->
  <!-- Camera joint -->
  <!-- Is located between the two back screw holes at ground level. -->
  <joint name="depth_camera_front_mount_tilted_to_depth_camera_front_camera_axis_aligned" type="fixed">
    <parent link="depth_camera_front_mount_tilted"/>
    <child link="depth_camera_front_camera_axis_aligned"/>
    <origin rpy="0 0 0" xyz="0.013 0.0 -0.02362"/>
  </joint>
  <!-- Camera axis aligned link -->
  <link name="depth_camera_front_camera_axis_aligned"/>
  <!-- Camera calibration joint -->
  <joint name="depth_camera_front_camera_axis_aligned_to_camera" type="fixed">
    <parent link="depth_camera_front_camera_axis_aligned"/>
    <child link="depth_camera_front_camera"/>
    <origin rpy="0.0 0.0 0.0" xyz="0.0 0.0 0.0"/>
  </joint>
  <!-- Camera link -->
  <link name="depth_camera_front_camera">
    <visual>
      <origin rpy="0 0 0" xyz="0.0 0.0 0.0"/>
      <geometry>
        <mesh filename="package://any_description/urdf/sensors/depth_camera/realsense_d435/realsense_d435.dae" scale=".001 .001 .001"/>
      </geometry>
      <material name="grey"/>
    </visual>
    <collision>
      <origin rpy="0 0 0" xyz="0.0125 0.0 0.0125"/>
      <geometry>
        <box size="0.025 0.089 0.025"/>
      </geometry>
      <material name="grey"/>
    </collision>
    <inertial>
      <origin rpy="0 0 0" xyz="0.011936651145 -0.000092349919 0.012257404184"/>
      <mass value="0.072"/>
      <inertia ixx="0.000045514558965" ixy="0.000000051943899" ixz="0.00000016511560" iyy="0.000006466822747" iyz="-0.000000001668932" izz="0.000046225339262"/>
    </inertial>
  </link>
  <!-- Camera parent joint -->
  <!-- Frame lies on the left ir camera according to any_realsense2_camera urdf. -->
  <joint name="depth_camera_front_camera_to_camera_parent" type="fixed">
    <parent link="depth_camera_front_camera"/>
    <child link="depth_camera_front_camera_parent"/>
    <origin rpy="0.0 0.0 0.0" xyz="0.02505 0.015 0.0125"/>
  </joint>
  <!-- Camera parent link -->
  <link name="depth_camera_front_camera_parent"/>
  <!-- Depth optical frame joint -->
  <joint name="depth_camera_front_camera_parent_to_depth_optical_frame" type="fixed">
    <parent link="depth_camera_front_camera_parent"/>
    <child link="depth_camera_front_depth_optical_frame"/>
    <origin rpy="-1.57079632679 0.0 -1.57079632679" xyz="0.0 0.0 0.0"/>
  </joint>
  <!-- Depth optical frame link -->
  <link name="depth_camera_front_depth_optical_frame"/>
  <!-- simulation or bagfile_is_played -->
  <!-- Gazebo plugin -->
  <gazebo reference="depth_camera_front_camera_parent">
    <sensor name="depth_camera_front_camera" type="depth">
      <always_on>1</always_on>
      <visualize>true</visualize>
      <update_rate>6</update_rate>
      <camera>
        <horizontal_fov>1.5917</horizontal_fov>
        <!-- 91.2 degrees -->
        <image>
          <width>424</width>
          <height>240</height>
          <format>R8G8B8</format>
        </image>
        <depth_camera>

            </depth_camera>
        <clip>
          <near>0.1</near>
          <far>10.0</far>
        </clip>
      </camera>
      <plugin filename="libgazebo_ros_openni_kinect.so" name="camera_controller">
        <alwaysOn>true</alwaysOn>
        <updateRate>0.0</updateRate>
        <cameraName>depth_camera_front</cameraName>
        <frameName>depth_camera_front_depth_optical_frame</frameName>
        <imageTopicName>rgb/image_raw</imageTopicName>
        <depthImageTopicName>depth/image_raw</depthImageTopicName>
        <pointCloudTopicName>depth/color/points</pointCloudTopicName>
        <cameraInfoTopicName>rgb/camera_info</cameraInfoTopicName>
        <depthImageCameraInfoTopicName>depth/camera_info</depthImageCameraInfoTopicName>
        <pointCloudCutoff>0.0</pointCloudCutoff>
        <hackBaseline>0.07</hackBaseline>
        <distortionK1>0.0</distortionK1>
        <distortionK2>0.0</distortionK2>
        <distortionK3>0.0</distortionK3>
        <distortionT1>0.0</distortionT1>
        <distortionT2>0.0</distortionT2>
        <CxPrime>0.0</CxPrime>
        <Cx>0.0</Cx>
        <Cy>0.0</Cy>
        <focalLength>0.0</focalLength>
      </plugin>
    </sensor>
  </gazebo>
  <!-- simulation -->
</robot>
