<?xml version="1.0" ?>
<!-- =================================================================================== -->
<!-- |    This document was autogenerated by xacro from /home/rgrandia/projects/anymal_ocs2/catkin_ws/src/anymal_rsl/anymal_c_rsl/anymal_cerberus_rsl/anymal_cerberus_rsl/urdf/anymal_cerberus_rsl.urdf.xacro | -->
<!-- |    EDITING THIS FILE BY HAND IS NOT RECOMMENDED                                 | -->
<!-- =================================================================================== -->
<!-- This file contains the description of the ANYmal robot. -->
<robot name="anymal">
  <!-- Colors -->
  <material name="anymal_material">
    <color rgba="0.7 0.7 0.7 1.0"/>
  </material>
  <!-- [kg * m^2] -->
  <!-- [m] -->
  <!-- measured -->
  <!-- Base link -->
  <link name="base">
    <visual>
      <origin rpy="0 0 0" xyz="0 0 0"/>
      <geometry>
        <mesh filename="package://anymal_c/urdf/base/base_3_1_1_mesh.dae" scale="1.0 1.0     1.0"/>
      </geometry>
    </visual>
    <collision>
      <origin rpy="0 0 0" xyz="0 0 0"/>
      <geometry>
        <box size="0.58 0.14 0.18"/>
      </geometry>
    </collision>
    <collision>
      <origin rpy="0 1.5707963267948966 0" xyz="0.21749999999999997 0.07 0"/>
      <geometry>
        <cylinder length="0.145" radius="0.09"/>
      </geometry>
    </collision>
    <collision>
      <origin rpy="0 1.5707963267948966 0" xyz="-0.21749999999999997 0.07 0"/>
      <geometry>
        <cylinder length="0.145" radius="0.09"/>
      </geometry>
    </collision>
    <collision>
      <origin rpy="0 1.5707963267948966 0" xyz="0.21749999999999997 -0.07 0"/>
      <geometry>
        <cylinder length="0.145" radius="0.09"/>
      </geometry>
    </collision>
    <collision>
      <origin rpy="0 1.5707963267948966 0" xyz="-0.21749999999999997 -0.07 0"/>
      <geometry>
        <cylinder length="0.145" radius="0.09"/>
      </geometry>
    </collision>
    <!-- Shell self filtering -->
    <self_filter>
      <origin rpy="0 0 0" xyz="0 0 0"/>
      <geometry>
        <box size="1.05 0.5 0.5"/>
      </geometry>
    </self_filter>
  </link>
  <!-- Fixed joint to add front handle link -->
  <joint name="base_to_front_handle" type="fixed">
    <parent link="base"/>
    <child link="front_handle"/>
    <origin rpy="0 0 0" xyz="0.36 0 0.13"/>
  </joint>
  <!-- Front handle link -->
  <!-- Added as a separate link due to limitation in point_cloud_self_filter -->
  <link name="front_handle">
    <collision>
      <origin rpy="0 0 0" xyz="0.0 0 0.015"/>
      <geometry>
        <box size="0.1 0.18 0.13"/>
      </geometry>
    </collision>
    <self_filter>
      <origin rpy="0 0 0" xyz="0.0 0 0.015"/>
      <geometry>
        <box size="0.1 0.18 0.13"/>
      </geometry>
    </self_filter>
  </link>
  <!-- Fixed joint to add top shell link -->
  <joint name="base_to_body_top" type="fixed">
    <parent link="base"/>
    <child link="body_top"/>
    <origin rpy="0 0 0" xyz="0 0 0.09"/>
  </joint>
  <!-- Body top link -->
  <!-- Added as a separate link due to limitation in point_cloud_self_filter -->
  <link name="body_top">
    <self_filter>
      <origin rpy="0 0 0" xyz="0 0 0"/>
      <geometry>
        <box size="1.05 0.4 0.005"/>
      </geometry>
    </self_filter>
  </link>
  <!-- Fixed joint to add dummy inertia link -->
  <joint name="base_to_base_inertia" type="fixed">
    <parent link="base"/>
    <child link="base_inertia"/>
    <origin rpy="0 0 0" xyz="0 0 0"/>
  </joint>
  <!-- Dummy inertia link, because KDL cannot have inertia on the base link -->
  <link name="base_inertia">
    <inertial>
      <origin rpy="0 0 0" xyz="-0.018 -0.002 0.024"/>
      <mass value="6.222"/>
      <inertia ixx="0.017938806" ixy="0.00387963" ixz="0.001500772" iyy="0.370887745" iyz="6.8963e-05" izz="0.372497653"/>
    </inertial>
  </link>
  <!-- [kg * m^2] -->
  <!-- Fixed joint base topshell -->
  <joint name="base_top_shell" type="fixed">
    <parent link="base"/>
    <child link="top_shell"/>
    <origin rpy="0 0 0" xyz="0 0 0"/>
  </joint>
  <!-- Top shell link -->
  <link name="top_shell">
    <visual>
      <origin rpy="0 0 0" xyz="0 0 0"/>
      <geometry>
        <mesh filename="package://anymal_c/urdf/base/shell/top_shell_3_1_1_mesh.dae" scale="1.0 1.0 1.0"/>
      </geometry>
    </visual>
    <inertial>
      <origin rpy="0 0 0" xyz="-0.00777 -0.00013 0.06523"/>
      <mass value="0.534"/>
      <inertia ixx="0.00664789486" ixy="1.247923e-05" ixz="0.00053990097" iyy="0.02587392411" iyz="3.7614e-07" izz="0.03152303792"/>
    </inertial>
  </link>
  <!-- [kg * m^2] -->
  <!-- Fixed joint base topshell -->
  <joint name="base_bottom_shell" type="fixed">
    <parent link="base"/>
    <child link="bottom_shell"/>
    <origin rpy="0 0 0" xyz="0 0 0"/>
  </joint>
  <!-- Bottom shell link -->
  <link name="bottom_shell">
    <visual>
      <origin rpy="0 0 0" xyz="0 0 0"/>
      <geometry>
        <mesh filename="package://anymal_c/urdf/base/shell/bottom_shell_3_1_1_mesh.dae" scale="1.0 1.0 1.0"/>
      </geometry>
    </visual>
    <inertial>
      <origin rpy="0 0 0" xyz="-0.00333 1e-05 -0.07705"/>
      <mass value="1.15"/>
      <inertia ixx="0.00927353677" ixy="5.41222e-06" ixz="9.039821e-05" iyy="0.06134388239" iyz="2.3042e-07" izz="0.06853531465"/>
    </inertial>
  </link>
  <!-- [kg * m^2] -->
  <!-- Fixed joint base remote -->
  <joint name="base_remote" type="fixed">
    <parent link="base"/>
    <child link="remote"/>
    <origin rpy="0 0 0" xyz="0 0 0"/>
  </joint>
  <!-- Remote link -->
  <link name="remote">
    <visual>
      <origin rpy="0 0 0" xyz="0 0 0"/>
      <geometry>
        <mesh filename="package://anymal_c/urdf/base/remote/remote_3_1_1_mesh.dae" scale="1.0 1.0     1.0"/>
      </geometry>
    </visual>
    <inertial>
      <origin rpy="0 0 0" xyz="-0.171 0.002 0.096"/>
      <mass value="0.3262"/>
      <inertia ixx="0.000528486" ixy="4.547e-05" ixz="1.10327e-05" iyy="0.001165035" iyz="7.4e-07" izz="0.00124026"/>
    </inertial>
  </link>
  <!-- [kg * m^2] -->
  <!-- Fixed joint base handle -->
  <joint name="base_handle" type="fixed">
    <parent link="base"/>
    <child link="handle"/>
    <origin rpy="0 0 0" xyz="0 0 0"/>
  </joint>
  <!-- Handle link -->
  <link name="handle">
    <visual>
      <origin rpy="0 0 0" xyz="0 0 0"/>
      <geometry>
        <mesh filename="package://anymal_c/urdf/base/handle/handle_3_1_1_mesh.dae" scale="1.0 1.0     1.0"/>
      </geometry>
    </visual>
    <inertial>
      <origin rpy="0 0 0" xyz="0.37801 0.0 0.1372"/>
      <mass value="0.314"/>
      <inertia ixx="0.001525739" ixy="0.0" ixz="6.272e-05" iyy="0.00071584" iyz="1e-09" izz="0.001164779"/>
    </inertial>
  </link>
  <!-- [kg * m^2] -->
  <!-- Fixed joint base battery -->
  <joint name="base_battery" type="fixed">
    <parent link="base"/>
    <child link="battery"/>
    <origin rpy="0 0 0" xyz="0 0 0"/>
  </joint>
  <!-- Shell link -->
  <link name="battery">
    <visual>
      <origin rpy="0 0 0" xyz="0 0 0"/>
      <geometry>
        <mesh filename="package://anymal_c/urdf/base/battery/battery_3_0_4_mesh.dae" scale="1.0 1.0     1.0"/>
      </geometry>
    </visual>
    <inertial>
      <origin rpy="0 0 0" xyz="-0.00067 -0.00023 -0.03362"/>
      <mass value="5.53425"/>
      <inertia ixx="0.00749474794" ixy="0.00016686282" ixz="7.82763e-05" iyy="0.0722338913" iyz="1.42902e-06" izz="0.07482717535"/>
    </inertial>
  </link>
  <!-- [kg * m^2] -->
  <!-- Fixed joint to add docking  -->
  <joint name="base_to_docking_hatch_cover" type="fixed">
    <parent link="base"/>
    <child link="docking_hatch_cover"/>
    <origin rpy="0 0 0" xyz="0.343 0.0 -0.07"/>
  </joint>
  <!-- Hatch cover link -->
  <link name="docking_hatch_cover">
    <!--  TODO(fgiraldez): add visual    -->
    <inertial>
      <origin rpy="0 0 0" xyz="-0.003 0.0 0.005"/>
      <mass value="0.065"/>
      <inertia ixx="0.00063283" ixy="0.0" ixz="3.45e-07" iyy="0.00110971" iyz="0.0" izz="0.00171883"/>
    </inertial>
  </link>
  <link name="imu_link"/>
  <joint name="imu_joint" type="fixed">
    <parent link="base"/>
    <child link="imu_link"/>
    <origin rpy="0.014786427188874516 -0.013839496499370383 1.5703623575180787" xyz="0.2488 0.00835 0.04628"/>
  </joint>
  <!-- [m] -->
  <joint name="base_to_bpearl_front" type="fixed">
    <origin rpy="1.5707963267948966 2.356194490192345 1.5707963267948966" xyz="0.429495 0.0 0.0"/>
    <parent link="base"/>
    <child link="bpearl_front"/>
  </joint>
  <!-- Frame used by point cloud messages -->
  <link name="bpearl_front">
    <visual>
      <!-- From the manual: X and Y axis in ROS convention are rotated of -90 deg w.r.t. rslidar's convention -->
      <origin rpy="0 0 -1.57079632679" xyz="0 0 0"/>
      <geometry>
        <mesh filename="package://rslidar_description/urdf/rslidar_bpearl/rslidar_bpearl.stl" scale=".001 .001 .001"/>
      </geometry>
      <material name="anymal_material"/>
    </visual>
    <collision>
      <!-- From the manual: X and Y axis in ROS convention are rotated of -90 deg w.r.t. rslidar's convention -->
      <origin rpy="0 0 -1.57079632679" xyz="0 0 0.055"/>
      <geometry>
        <box size="0.1 0.1 0.11"/>
      </geometry>
    </collision>
    <!-- Product of inertia are computed in the same frame as the rslidar's manual -->
    <inertial>
      <mass value="0.95"/>
      <origin xyz="-0.00002729                      -0.000960602                      0.035445923"/>
      <inertia ixx="0.00278457" ixy="-0.00000809" ixz="0.000000099" iyy="0.002730237" iyz="-0.000001661" izz="0.00168635"/>
    </inertial>
  </link>
  <!-- Frame used for self filter -->
  <joint name="bpearl_front_to_bpearl_front_beam_origin" type="fixed">
    <parent link="bpearl_front"/>
    <child link="bpearl_front_beam_origin"/>
    <origin rpy="0 0 0" xyz="0 0 0.09427"/>
  </joint>
  <link name="bpearl_front_beam_origin"/>
  <!-- TODO: which Gazebo plugin should we use for simulation of the bpearl? -->
  <joint name="base_to_bpearl_front_protection_bars" type="fixed">
    <origin rpy="0 0 0.0" xyz="0.414495 0.0 0.0"/>
    <parent link="base"/>
    <child link="bpearl_front_protection_bars"/>
  </joint>
  <link name="bpearl_front_protection_bars">
    <visual>
      <origin rpy="0 0 3.141592653589793" xyz="0 0 0"/>
      <geometry>
        <mesh filename="package://anymal_c_rsl/urdf/protectors/bpearl_straight_1_1_0_protection_bars.stl" scale=".001 .001 .001"/>
      </geometry>
      <material name="anymal_material"/>
    </visual>
    <collision>
      <origin rpy="0 0 0" xyz="0.0966926 0.0 -0.0085"/>
      <geometry>
        <box size="0.1933852 0.2515831 0.187"/>
      </geometry>
    </collision>
    <inertial>
      <mass value="0.796"/>
      <origin xyz=" -0.051923207516                       0.00006483751                       -0.005401341"/>
      <inertia ixx="0.005848548" ixy="0.000002384" ixz="0.000085561" iyy="0.003655467" iyz="-0.000001227" izz="0.005569897"/>
    </inertial>
  </link>
  <!-- [m] -->
  <joint name="base_to_bpearl_rear" type="fixed">
    <origin rpy="1.5707963267948966 2.356194490192345 4.71238898038469" xyz="-0.429495 0.0 0.0"/>
    <parent link="base"/>
    <child link="bpearl_rear"/>
  </joint>
  <!-- Frame used by point cloud messages -->
  <link name="bpearl_rear">
    <visual>
      <!-- From the manual: X and Y axis in ROS convention are rotated of -90 deg w.r.t. rslidar's convention -->
      <origin rpy="0 0 -1.57079632679" xyz="0 0 0"/>
      <geometry>
        <mesh filename="package://rslidar_description/urdf/rslidar_bpearl/rslidar_bpearl.stl" scale=".001 .001 .001"/>
      </geometry>
      <material name="anymal_material"/>
    </visual>
    <collision>
      <!-- From the manual: X and Y axis in ROS convention are rotated of -90 deg w.r.t. rslidar's convention -->
      <origin rpy="0 0 -1.57079632679" xyz="0 0 0.055"/>
      <geometry>
        <box size="0.1 0.1 0.11"/>
      </geometry>
    </collision>
    <!-- Product of inertia are computed in the same frame as the rslidar's manual -->
    <inertial>
      <mass value="0.95"/>
      <origin xyz="-0.00002729                      -0.000960602                      0.035445923"/>
      <inertia ixx="0.00278457" ixy="-0.00000809" ixz="0.000000099" iyy="0.002730237" iyz="-0.000001661" izz="0.00168635"/>
    </inertial>
  </link>
  <!-- Frame used for self filter -->
  <joint name="bpearl_rear_to_bpearl_rear_beam_origin" type="fixed">
    <parent link="bpearl_rear"/>
    <child link="bpearl_rear_beam_origin"/>
    <origin rpy="0 0 0" xyz="0 0 0.09427"/>
  </joint>
  <link name="bpearl_rear_beam_origin"/>
  <!-- TODO: which Gazebo plugin should we use for simulation of the bpearl? -->
  <joint name="base_to_bpearl_rear_protection_bars" type="fixed">
    <origin rpy="0 0 3.141592653589793" xyz="-0.414495 0.0 0.0"/>
    <parent link="base"/>
    <child link="bpearl_rear_protection_bars"/>
  </joint>
  <link name="bpearl_rear_protection_bars">
    <visual>
      <origin rpy="0 0 3.141592653589793" xyz="0 0 0"/>
      <geometry>
        <mesh filename="package://anymal_c_rsl/urdf/protectors/bpearl_straight_1_1_0_protection_bars.stl" scale=".001 .001 .001"/>
      </geometry>
      <material name="anymal_material"/>
    </visual>
    <collision>
      <origin rpy="0 0 0" xyz="0.0966926 0.0 -0.0085"/>
      <geometry>
        <box size="0.1933852 0.2515831 0.187"/>
      </geometry>
    </collision>
    <inertial>
      <mass value="0.796"/>
      <origin xyz=" -0.051923207516                       0.00006483751                       -0.005401341"/>
      <inertia ixx="0.005848548" ixy="0.000002384" ixz="0.000085561" iyy="0.003655467" iyz="-0.000001227" izz="0.005569897"/>
    </inertial>
  </link>
  <!-- Parent to cage joint, located between mounting plate on trunk and the cage -->
  <joint name="base_to_perception_head_cage" type="fixed">
    <parent link="base"/>
    <child link="perception_head_cage"/>
    <origin rpy="0 0 0" xyz="-0.364 0.0 0.0"/>
  </joint>
  <!-- Velodyne cage link -->
  <link name="perception_head_cage">
    <visual>
      <origin rpy="0.0 0.0 0.0" xyz="0.0 0.0 0.0"/>
      <geometry>
        <mesh filename="package://anymal_c_rsl/urdf/modules/perception_head/perception_head.stl" scale=".001 .001 .001"/>
      </geometry>
      <material name="anymal_material"/>
    </visual>
    <collision>
      <origin rpy="0 0 0" xyz="0.0080435 0.0 0.1614"/>
      <geometry>
        <box size="0.14151 0.21544 0.1768"/>
      </geometry>
    </collision>
    <inertial>
      <mass value="0.3879"/>
      <origin xyz="-0.01163                      -0.0000109                      0.15412"/>
      <inertia ixx="0.011412" ixy="-0.00000037" ixz="-0.00086643" iyy="0.010402" iyz="0.00000038" izz="0.001749"/>
    </inertial>
  </link>
  <!-- [kg * m^2] -->
  <!-- parent to sensor joint -->
  <joint name="perception_head_cage_to_lidar" type="fixed">
    <parent link="perception_head_cage"/>
    <child link="lidar"/>
    <origin rpy="0.0 0.0 -1.5707963267948966" xyz="0.0 0.0 0.1422"/>
  </joint>
  <!-- Velodyne sensor link -->
  <link name="lidar">
    <inertial>
      <origin rpy="0.0 0.0 0.0" xyz="-0.012 0.001 -0.008"/>
      <mass value="0.695"/>
      <inertia ixx="0.000846765" ixy="6.9565e-05" ixz="0.00027111" iyy="0.001367583" iyz="5.8984e-05" izz="0.001363673"/>
    </inertial>
    <visual>
      <origin xyz="0 0 0"/>
      <geometry>
        <mesh filename="package://anymal_c/urdf/base/sensors/lidar/velodyne_3_1_1_mesh.dae"/>
      </geometry>
    </visual>
  </link>
  <!-- simulation -->
  <!-- Fixed joint base to interface hatch -->
  <joint name="base_to_interface_hatch" type="fixed">
    <parent link="base"/>
    <child link="interface_hatch"/>
    <origin rpy="0 0 0" xyz="0.0 0.0 0.073"/>
  </joint>
  <!-- Interface hatch link -->
  <link name="interface_hatch">
    <visual>
      <origin rpy="0.0 0.0 0.0" xyz="0.0 0.0 0.0"/>
      <geometry>
        <mesh filename="package://anymal_c_rsl/urdf/modules/interface_hatch/interface_hatch.stl" scale=".001 .001 .001"/>
      </geometry>
      <material name="anymal_material"/>
    </visual>
    <collision>
      <origin rpy="0 0 0" xyz="0.1158036 0.0 0.0245"/>
      <geometry>
        <box size="0.1817832 0.1296570 0.055"/>
      </geometry>
    </collision>
    <inertial>
      <mass value="0.293687504"/>
      <origin xyz="0.115318879473                      0.000251718520                      0.021931226692"/>
      <inertia ixx="0.000687763980844" ixy="-0.000001080796219" ixz="0.000002713907006" iyy="0.001176920719975" iyz="-0.000000364550324" izz="0.001716726006302"/>
    </inertial>
  </link>
  <!-- [kg * m^2] -->
  <!-- Fixed joint base hatch -->
  <joint name="interface_hatch_hatch" type="fixed">
    <parent link="interface_hatch"/>
    <child link="hatch"/>
    <origin rpy="0 0 0" xyz="0.116 0.0 0.0475"/>
  </joint>
  <!-- Hatch link -->
  <link name="hatch">
    <visual>
      <origin rpy="0 0 0" xyz="0 0 0"/>
      <geometry>
        <mesh filename="package://anymal_c/urdf/base/hatch/hatch_3_1_1_mesh.dae" scale="1.0 1.0 1.0"/>
      </geometry>
    </visual>
    <inertial>
      <origin rpy="0 0 0" xyz="0.116 0.0 0.0758"/>
      <mass value="0.142"/>
      <inertia ixx="0.001" ixy="0.0" ixz="0.0" iyy="0.001" iyz="0.0" izz="0.001"/>
    </inertial>
  </link>
  <!--<xacro:hatch/> -->
  <!-- [rad] -->
  <!-- [rad] -->
  <!-- joint base HAA -->
  <joint name="base_LF_HAA" type="fixed">
    <parent link="base"/>
    <child link="LF_HAA"/>
    <origin rpy="2.6179938779914944 0 0.0" xyz="0.2999 0.104 0.0"/>
  </joint>
  <!-- [m] -->
  <!-- [A] -->
  <!-- Drive link -->
  <link name="LF_HAA">
    <visual>
      <origin rpy="0 0 0" xyz="0 0 0"/>
      <geometry>
        <mesh filename="package://anymal_c/urdf/leg/drives/drive_3_0_2_mesh.dae" scale="1.0 1.0     1.0"/>
      </geometry>
    </visual>
    <inertial>
      <origin rpy="0 0 0" xyz="-0.063 7e-05 0.00046"/>
      <mass value="2.04"/>
      <inertia ixx="0.001053013" ixy="4.527e-05" ixz="8.855e-05" iyy="0.001805509" iyz="9.909e-05" izz="0.001765827"/>
    </inertial>
  </link>
  <!-- joint Drive output -->
  <joint name="LF_HAA" type="revolute">
    <parent link="LF_HAA"/>
    <child link="LF_HIP"/>
    <origin rpy="0 0 0" xyz="0 0 0"/>
    <axis xyz="1 0 0"/>
    <limit command_effort="80.0" current="32.0" effort="80.0" gear_velocity="7.5" lower="-0.72" upper="0.49" velocity="7.5"/>
    <dynamics damping="0.0" friction="0.0"/>
  </joint>
  <!-- Drive output link -->
  <link name="LF_HIP">
    <inertial>
      <origin rpy="0 0 0" xyz="0 0 0"/>
      <mass value="0.001"/>
      <inertia ixx="0.000001" ixy="0.0" ixz="0.0" iyy="0.000001" iyz="0.0" izz="0.000001"/>
    </inertial>
  </link>
  <!-- [kg * m^2] -->
  <!-- joint HAA hip -->
  <joint name="LF_HIP_LF_hip_fixed" type="fixed">
    <parent link="LF_HIP"/>
    <child link="LF_hip_fixed"/>
    <origin rpy="-2.6179938779914944 0 0.0" xyz="0 0 0"/>
  </joint>
  <!-- Hip link -->
  <link name="LF_hip_fixed">
    <visual>
      <origin rpy="0 0 0.0" xyz="0 0 0"/>
      <geometry>
        <mesh filename="package://anymal_c/urdf/leg/hip/hip_3_1_1_mesh.dae" scale="1.0 1.0     1.0"/>
      </geometry>
    </visual>
    <inertial>
      <origin rpy="0 0 0" xyz="0.048 0.008 -0.003"/>
      <mass value="0.74"/>
      <inertia ixx="0.001393106" ixy="8.4012e-05" ixz="2.3378e-05" iyy="0.003798579" iyz="7.1319e-05" izz="0.003897509"/>
    </inertial>
  </link>
  <!-- [rad] -->
  <!-- joint hip HFE -->
  <joint name="LF_hip_fixed_LF_HFE" type="fixed">
    <parent link="LF_hip_fixed"/>
    <child link="LF_HFE"/>
    <origin rpy="0 0 1.5707963267948966" xyz="0.0599 0.08381 0.0"/>
  </joint>
  <!-- [m] -->
  <!-- [A] -->
  <!-- Drive link -->
  <link name="LF_HFE">
    <visual>
      <origin rpy="0 0 0" xyz="0 0 0"/>
      <geometry>
        <mesh filename="package://anymal_c/urdf/leg/drives/drive_3_0_2_mesh.dae" scale="1.0 1.0     1.0"/>
      </geometry>
    </visual>
    <collision>
      <origin rpy="0 1.5707963267948966 0" xyz="-0.07 0 0"/>
      <geometry>
        <cylinder length="0.14" radius="0.05"/>
      </geometry>
    </collision>
    <inertial>
      <origin rpy="0 0 0" xyz="-0.063 7e-05 0.00046"/>
      <mass value="2.04"/>
      <inertia ixx="0.001053013" ixy="4.527e-05" ixz="8.855e-05" iyy="0.001805509" iyz="9.909e-05" izz="0.001765827"/>
    </inertial>
  </link>
  <!-- joint Drive output -->
  <joint name="LF_HFE" type="revolute">
    <parent link="LF_HFE"/>
    <child link="LF_THIGH"/>
    <origin rpy="0 0 0" xyz="0 0 0"/>
    <axis xyz="1 0 0"/>
    <limit command_effort="80.0" current="32.0" effort="80.0" gear_velocity="7.5" lower="-9.42477796076938" upper="9.42477796076938" velocity="7.5"/>
    <dynamics damping="0.0" friction="0.0"/>
  </joint>
  <!-- Drive output link -->
  <link name="LF_THIGH">
    <inertial>
      <origin rpy="0 0 0" xyz="0 0 0"/>
      <mass value="0.001"/>
      <inertia ixx="0.000001" ixy="0.0" ixz="0.0" iyy="0.000001" iyz="0.0" izz="0.000001"/>
    </inertial>
  </link>
  <!-- [m] -->
  <!-- measured -->
  <!-- joint HFE thigh -->
  <joint name="LF_THIGH_LF_thigh_fixed" type="fixed">
    <parent link="LF_THIGH"/>
    <child link="LF_thigh_fixed"/>
    <origin rpy="0 0 -1.5707963267948966" xyz="0 0 0"/>
  </joint>
  <!-- Thigh link -->
  <link name="LF_thigh_fixed">
    <visual>
      <origin rpy="0 0 0.0" xyz="0 0 0"/>
      <geometry>
        <mesh filename="package://anymal_c/urdf/leg/thigh/thigh_3_1_1_mesh.dae" scale="1.0 1.0     1.0"/>
      </geometry>
    </visual>
    <!-- Thigh collision -->
    <collision>
      <origin rpy="1.5707963267948966 0 0" xyz="0 0.04 0"/>
      <geometry>
        <cylinder length="0.08" radius="0.065"/>
      </geometry>
    </collision>
    <collision>
      <origin rpy="0 0 0" xyz="0 0.03 -0.1413135"/>
      <geometry>
        <box size="0.07500000000000001 0.06 0.282627"/>
      </geometry>
    </collision>
    <inertial>
      <origin rpy="0 0 0" xyz="0.0 0.018 -0.169"/>
      <mass value="1.03"/>
      <inertia ixx="0.018644469" ixy="5.2e-08" ixz="1.0157e-05" iyy="0.019312599" iyz="0.002520077" izz="0.002838361"/>
    </inertial>
  </link>
  <!-- [rad] -->
  <!-- joint thigh KFE -->
  <joint name="LF_thigh_fixed_LF_KFE" type="fixed">
    <parent link="LF_thigh_fixed"/>
    <child link="LF_KFE"/>
    <origin rpy="0 0 1.5707963267948966" xyz="0.0 0.1003 -0.285"/>
  </joint>
  <!-- [m] -->
  <!-- [A] -->
  <!-- Drive link -->
  <link name="LF_KFE">
    <visual>
      <origin rpy="0 0 0" xyz="0 0 0"/>
      <geometry>
        <mesh filename="package://anymal_c/urdf/leg/drives/drive_3_0_2_mesh.dae" scale="1.0 1.0     1.0"/>
      </geometry>
    </visual>
    <collision>
      <origin rpy="0 1.5707963267948966 0" xyz="-0.07 0 0"/>
      <geometry>
        <cylinder length="0.14" radius="0.05"/>
      </geometry>
    </collision>
    <inertial>
      <origin rpy="0 0 0" xyz="-0.063 7e-05 0.00046"/>
      <mass value="2.04"/>
      <inertia ixx="0.001053013" ixy="4.527e-05" ixz="8.855e-05" iyy="0.001805509" iyz="9.909e-05" izz="0.001765827"/>
    </inertial>
  </link>
  <!-- joint Drive output -->
  <joint name="LF_KFE" type="revolute">
    <parent link="LF_KFE"/>
    <child link="LF_SHANK"/>
    <origin rpy="0 0 0" xyz="0 0 0"/>
    <axis xyz="1 0 0"/>
    <limit command_effort="80.0" current="32.0" effort="80.0" gear_velocity="7.5" lower="-9.42477796076938" upper="9.42477796076938" velocity="7.5"/>
    <dynamics damping="0.0" friction="0.0"/>
  </joint>
  <!-- Drive output link -->
  <link name="LF_SHANK">
    <inertial>
      <origin rpy="0 0 0" xyz="0 0 0"/>
      <mass value="0.001"/>
      <inertia ixx="0.000001" ixy="0.0" ixz="0.0" iyy="0.000001" iyz="0.0" izz="0.000001"/>
    </inertial>
  </link>
  <!-- [m] -->
  <!-- measured -->
  <!-- joint KFE shank -->
  <joint name="LF_shank_LF_shank_fixed" type="fixed">
    <parent link="LF_SHANK"/>
    <child link="LF_shank_fixed"/>
    <origin rpy="0 0 -1.5707963267948966" xyz="0 0 0"/>
  </joint>
  <!-- Shank link -->
  <link name="LF_shank_fixed">
    <visual>
      <origin rpy="0 0 0.0" xyz="0 0 0"/>
      <geometry>
        <mesh filename="package://anymal_c/urdf/leg/shank/shank_3_1_1_mesh.dae" scale="1.0 1.0     1.0"/>
      </geometry>
    </visual>
    <!-- Shank collision -->
    <collision>
      <origin rpy="1.5707963267948966 0 0" xyz="0 0.02 0"/>
      <geometry>
        <cylinder length="0.04" radius="0.06"/>
      </geometry>
    </collision>
    <collision>
      <origin rpy="1.5707963267948966 0 0" xyz="0.057499 0.02 0"/>
      <geometry>
        <box size="0.114998 0.0675 0.04"/>
      </geometry>
    </collision>
    <inertial>
      <origin rpy="0 0 0" xyz="0.03463 0.00688 0.00098"/>
      <mass value="0.33742"/>
      <inertia ixx="0.00032748005" ixy="2.142561e-05" ixz="1.33942e-05" iyy="0.00110974122" iyz="7.601e-08" izz="0.00089388521"/>
    </inertial>
  </link>
  <!-- Leg configurations: xx (knees bent inwards), xo (knees bent backwards) -->
  <!-- joint shank foot -->
  <joint name="LF_shank_fixed_LF_FOOT" type="fixed">
    <parent link="LF_shank_fixed"/>
    <child link="LF_FOOT"/>
    <origin rpy="0 0 0" xyz="0.08795 0.01305 -0.33797"/>
  </joint>
  <!-- Foot link -->
  <link name="LF_FOOT">
    <visual>
      <origin rpy="0 0 -0.7853981633974483" xyz="0 0 0"/>
      <geometry>
        <mesh filename="package://anymal_c/urdf/leg/foot/foot_3_1_1_mesh.dae" scale="1.0 1.0     1.0"/>
      </geometry>
    </visual>
    <!-- Adapter collision -->
    <collision>
      <origin rpy="0 0 0" xyz="0 0 0.168985"/>
      <geometry>
        <cylinder length="0.282504" radius="0.0175"/>
      </geometry>
    </collision>
    <!-- Foot collision -->
    <collision>
      <origin xyz="0 0 0.0225"/>
      <geometry>
        <sphere radius="0.03"/>
      </geometry>
    </collision>
    <inertial>
      <origin rpy="0 0 0" xyz="0.00948 -0.00948 0.1468"/>
      <mass value="0.25"/>
      <inertia ixx="0.00317174097" ixy="2.63048e-06" ixz="6.815581e-05" iyy="0.00317174092" iyz="6.815583e-05" izz="8.319196e-05"/>
    </inertial>
  </link>
  <!-- Gazebo customization -->
  <gazebo reference="LF_FOOT">
    <kp>1000000.0</kp>
    <kd>100.0</kd>
    <mu1>0.8</mu1>
    <mu2>0.8</mu2>
  </gazebo>
  <!-- [rad] -->
  <!-- [rad] -->
  <!-- joint base HAA -->
  <joint name="base_RF_HAA" type="fixed">
    <parent link="base"/>
    <child link="RF_HAA"/>
    <origin rpy="-2.6179938779914944 0 0.0" xyz="0.2999 -0.104 0.0"/>
  </joint>
  <!-- [m] -->
  <!-- [A] -->
  <!-- Drive link -->
  <link name="RF_HAA">
    <visual>
      <origin rpy="0 0 0" xyz="0 0 0"/>
      <geometry>
        <mesh filename="package://anymal_c/urdf/leg/drives/drive_3_0_2_mesh.dae" scale="1.0 1.0     1.0"/>
      </geometry>
    </visual>
    <inertial>
      <origin rpy="0 0 0" xyz="-0.063 7e-05 0.00046"/>
      <mass value="2.04"/>
      <inertia ixx="0.001053013" ixy="4.527e-05" ixz="8.855e-05" iyy="0.001805509" iyz="9.909e-05" izz="0.001765827"/>
    </inertial>
  </link>
  <!-- joint Drive output -->
  <joint name="RF_HAA" type="revolute">
    <parent link="RF_HAA"/>
    <child link="RF_HIP"/>
    <origin rpy="0 0 0" xyz="0 0 0"/>
    <axis xyz="1 0 0"/>
    <limit command_effort="80.0" current="32.0" effort="80.0" gear_velocity="7.5" lower="-0.49" upper="0.72" velocity="7.5"/>
    <dynamics damping="0.0" friction="0.0"/>
  </joint>
  <!-- Drive output link -->
  <link name="RF_HIP">
    <inertial>
      <origin rpy="0 0 0" xyz="0 0 0"/>
      <mass value="0.001"/>
      <inertia ixx="0.000001" ixy="0.0" ixz="0.0" iyy="0.000001" iyz="0.0" izz="0.000001"/>
    </inertial>
  </link>
  <!-- [kg * m^2] -->
  <!-- joint HAA hip -->
  <joint name="RF_HIP_RF_hip_fixed" type="fixed">
    <parent link="RF_HIP"/>
    <child link="RF_hip_fixed"/>
    <origin rpy="2.6179938779914944 0 0.0" xyz="0 0 0"/>
  </joint>
  <!-- Hip link -->
  <link name="RF_hip_fixed">
    <visual>
      <origin rpy="0 0 0.0" xyz="0 0 0"/>
      <geometry>
        <mesh filename="package://anymal_c/urdf/leg/hip/hip_3_1_1_mesh_mirrored.dae" scale="1.0 1.0     1.0"/>
      </geometry>
    </visual>
    <inertial>
      <origin rpy="0 0 0" xyz="0.048 -0.008 -0.003"/>
      <mass value="0.74"/>
      <inertia ixx="0.001393106" ixy="-8.4012e-05" ixz="2.3378e-05" iyy="0.003798579" iyz="-7.1319e-05" izz="0.003897509"/>
    </inertial>
  </link>
  <!-- [rad] -->
  <!-- joint hip HFE -->
  <joint name="RF_hip_fixed_RF_HFE" type="fixed">
    <parent link="RF_hip_fixed"/>
    <child link="RF_HFE"/>
    <origin rpy="0 0 -1.5707963267948966" xyz="0.0599 -0.08381 0.0"/>
  </joint>
  <!-- [m] -->
  <!-- [A] -->
  <!-- Drive link -->
  <link name="RF_HFE">
    <visual>
      <origin rpy="0 0 0" xyz="0 0 0"/>
      <geometry>
        <mesh filename="package://anymal_c/urdf/leg/drives/drive_3_0_2_mesh.dae" scale="1.0 1.0     1.0"/>
      </geometry>
    </visual>
    <collision>
      <origin rpy="0 1.5707963267948966 0" xyz="-0.07 0 0"/>
      <geometry>
        <cylinder length="0.14" radius="0.05"/>
      </geometry>
    </collision>
    <inertial>
      <origin rpy="0 0 0" xyz="-0.063 7e-05 0.00046"/>
      <mass value="2.04"/>
      <inertia ixx="0.001053013" ixy="4.527e-05" ixz="8.855e-05" iyy="0.001805509" iyz="9.909e-05" izz="0.001765827"/>
    </inertial>
  </link>
  <!-- joint Drive output -->
  <joint name="RF_HFE" type="revolute">
    <parent link="RF_HFE"/>
    <child link="RF_THIGH"/>
    <origin rpy="0 0 0" xyz="0 0 0"/>
    <axis xyz="-1 0 0"/>
    <limit command_effort="80.0" current="32.0" effort="80.0" gear_velocity="7.5" lower="-9.42477796076938" upper="9.42477796076938" velocity="7.5"/>
    <dynamics damping="0.0" friction="0.0"/>
  </joint>
  <!-- Drive output link -->
  <link name="RF_THIGH">
    <inertial>
      <origin rpy="0 0 0" xyz="0 0 0"/>
      <mass value="0.001"/>
      <inertia ixx="0.000001" ixy="0.0" ixz="0.0" iyy="0.000001" iyz="0.0" izz="0.000001"/>
    </inertial>
  </link>
  <!-- [m] -->
  <!-- measured -->
  <!-- joint HFE thigh -->
  <joint name="RF_THIGH_RF_thigh_fixed" type="fixed">
    <parent link="RF_THIGH"/>
    <child link="RF_thigh_fixed"/>
    <origin rpy="0 0 1.5707963267948966" xyz="0 0 0"/>
  </joint>
  <!-- Thigh link -->
  <link name="RF_thigh_fixed">
    <visual>
      <origin rpy="0 0 -3.141592653589793" xyz="0 0 0"/>
      <geometry>
        <mesh filename="package://anymal_c/urdf/leg/thigh/thigh_3_1_1_mesh.dae" scale="1.0 1.0     1.0"/>
      </geometry>
    </visual>
    <!-- Thigh collision -->
    <collision>
      <origin rpy="1.5707963267948966 0 0" xyz="0 -0.04 0"/>
      <geometry>
        <cylinder length="0.08" radius="0.065"/>
      </geometry>
    </collision>
    <collision>
      <origin rpy="0 0 0" xyz="0 -0.03 -0.1413135"/>
      <geometry>
        <box size="0.07500000000000001 0.06 0.282627"/>
      </geometry>
    </collision>
    <inertial>
      <origin rpy="0 0 0" xyz="0.0 -0.018 -0.169"/>
      <mass value="1.03"/>
      <inertia ixx="0.018644469" ixy="-5.2e-08" ixz="1.0157e-05" iyy="0.019312599" iyz="-0.002520077" izz="0.002838361"/>
    </inertial>
  </link>
  <!-- [rad] -->
  <!-- joint thigh KFE -->
  <joint name="RF_thigh_fixed_RF_KFE" type="fixed">
    <parent link="RF_thigh_fixed"/>
    <child link="RF_KFE"/>
    <origin rpy="0 0 -1.5707963267948966" xyz="0.0 -0.1003 -0.285"/>
  </joint>
  <!-- [m] -->
  <!-- [A] -->
  <!-- Drive link -->
  <link name="RF_KFE">
    <visual>
      <origin rpy="0 0 0" xyz="0 0 0"/>
      <geometry>
        <mesh filename="package://anymal_c/urdf/leg/drives/drive_3_0_2_mesh.dae" scale="1.0 1.0     1.0"/>
      </geometry>
    </visual>
    <collision>
      <origin rpy="0 1.5707963267948966 0" xyz="-0.07 0 0"/>
      <geometry>
        <cylinder length="0.14" radius="0.05"/>
      </geometry>
    </collision>
    <inertial>
      <origin rpy="0 0 0" xyz="-0.063 7e-05 0.00046"/>
      <mass value="2.04"/>
      <inertia ixx="0.001053013" ixy="4.527e-05" ixz="8.855e-05" iyy="0.001805509" iyz="9.909e-05" izz="0.001765827"/>
    </inertial>
  </link>
  <!-- joint Drive output -->
  <joint name="RF_KFE" type="revolute">
    <parent link="RF_KFE"/>
    <child link="RF_SHANK"/>
    <origin rpy="0 0 0" xyz="0 0 0"/>
    <axis xyz="-1 0 0"/>
    <limit command_effort="80.0" current="32.0" effort="80.0" gear_velocity="7.5" lower="-9.42477796076938" upper="9.42477796076938" velocity="7.5"/>
    <dynamics damping="0.0" friction="0.0"/>
  </joint>
  <!-- Drive output link -->
  <link name="RF_SHANK">
    <inertial>
      <origin rpy="0 0 0" xyz="0 0 0"/>
      <mass value="0.001"/>
      <inertia ixx="0.000001" ixy="0.0" ixz="0.0" iyy="0.000001" iyz="0.0" izz="0.000001"/>
    </inertial>
  </link>
  <!-- [m] -->
  <!-- measured -->
  <!-- joint KFE shank -->
  <joint name="RF_shank_RF_shank_fixed" type="fixed">
    <parent link="RF_SHANK"/>
    <child link="RF_shank_fixed"/>
    <origin rpy="0 0 1.5707963267948966" xyz="0 0 0"/>
  </joint>
  <!-- Shank link -->
  <link name="RF_shank_fixed">
    <visual>
      <origin rpy="0 0 0.0" xyz="0 0 0"/>
      <geometry>
        <mesh filename="package://anymal_c/urdf/leg/shank/shank_3_1_1_mesh_mirrored.dae" scale="1.0 1.0     1.0"/>
      </geometry>
    </visual>
    <!-- Shank collision -->
    <collision>
      <origin rpy="1.5707963267948966 0 0" xyz="0 -0.02 0"/>
      <geometry>
        <cylinder length="0.04" radius="0.06"/>
      </geometry>
    </collision>
    <collision>
      <origin rpy="1.5707963267948966 0 0" xyz="0.057499 -0.02 0"/>
      <geometry>
        <box size="0.114998 0.0675 0.04"/>
      </geometry>
    </collision>
    <inertial>
      <origin rpy="0 0 0" xyz="0.03463 -0.00688 0.00098"/>
      <mass value="0.33742"/>
      <inertia ixx="0.00032748005" ixy="-2.142561e-05" ixz="1.33942e-05" iyy="0.00110974122" iyz="-7.601e-08" izz="0.00089388521"/>
    </inertial>
  </link>
  <!-- Leg configurations: xx (knees bent inwards), xo (knees bent backwards) -->
  <!-- joint shank foot -->
  <joint name="RF_shank_fixed_RF_FOOT" type="fixed">
    <parent link="RF_shank_fixed"/>
    <child link="RF_FOOT"/>
    <origin rpy="0 0 0" xyz="0.08795 -0.01305 -0.33797"/>
  </joint>
  <!-- Foot link -->
  <link name="RF_FOOT">
    <visual>
      <origin rpy="0 0 0.7853981633974483" xyz="0 0 0"/>
      <geometry>
        <mesh filename="package://anymal_c/urdf/leg/foot/foot_3_1_1_mesh.dae" scale="1.0 1.0     1.0"/>
      </geometry>
    </visual>
    <!-- Adapter collision -->
    <collision>
      <origin rpy="0 0 0" xyz="0 0 0.168985"/>
      <geometry>
        <cylinder length="0.282504" radius="0.0175"/>
      </geometry>
    </collision>
    <!-- Foot collision -->
    <collision>
      <origin xyz="0 0 0.0225"/>
      <geometry>
        <sphere radius="0.03"/>
      </geometry>
    </collision>
    <inertial>
      <origin rpy="0 0 0" xyz="0.00948 0.00948 0.1468"/>
      <mass value="0.25"/>
      <inertia ixx="0.00317174097" ixy="-2.63048e-06" ixz="6.815581e-05" iyy="0.00317174092" iyz="-6.815583e-05" izz="8.319196e-05"/>
    </inertial>
  </link>
  <!-- Gazebo customization -->
  <gazebo reference="RF_FOOT">
    <kp>1000000.0</kp>
    <kd>100.0</kd>
    <mu1>0.8</mu1>
    <mu2>0.8</mu2>
  </gazebo>
  <!-- [rad] -->
  <!-- [rad] -->
  <!-- joint base HAA -->
  <joint name="base_LH_HAA" type="fixed">
    <parent link="base"/>
    <child link="LH_HAA"/>
    <origin rpy="-2.6179938779914944 0 -3.141592653589793" xyz="-0.2999 0.104 0.0"/>
  </joint>
  <!-- [m] -->
  <!-- [A] -->
  <!-- Drive link -->
  <link name="LH_HAA">
    <visual>
      <origin rpy="0 0 0" xyz="0 0 0"/>
      <geometry>
        <mesh filename="package://anymal_c/urdf/leg/drives/drive_3_0_2_mesh.dae" scale="1.0 1.0     1.0"/>
      </geometry>
    </visual>
    <inertial>
      <origin rpy="0 0 0" xyz="-0.063 7e-05 0.00046"/>
      <mass value="2.04"/>
      <inertia ixx="0.001053013" ixy="4.527e-05" ixz="8.855e-05" iyy="0.001805509" iyz="9.909e-05" izz="0.001765827"/>
    </inertial>
  </link>
  <!-- joint Drive output -->
  <joint name="LH_HAA" type="revolute">
    <parent link="LH_HAA"/>
    <child link="LH_HIP"/>
    <origin rpy="0 0 0" xyz="0 0 0"/>
    <axis xyz="-1 0 0"/>
    <limit command_effort="80.0" current="32.0" effort="80.0" gear_velocity="7.5" lower="-0.72" upper="0.49" velocity="7.5"/>
    <dynamics damping="0.0" friction="0.0"/>
  </joint>
  <!-- Drive output link -->
  <link name="LH_HIP">
    <inertial>
      <origin rpy="0 0 0" xyz="0 0 0"/>
      <mass value="0.001"/>
      <inertia ixx="0.000001" ixy="0.0" ixz="0.0" iyy="0.000001" iyz="0.0" izz="0.000001"/>
    </inertial>
  </link>
  <!-- [kg * m^2] -->
  <!-- joint HAA hip -->
  <joint name="LH_HIP_LH_hip_fixed" type="fixed">
    <parent link="LH_HIP"/>
    <child link="LH_hip_fixed"/>
    <origin rpy="-2.6179938779914944 0 -3.141592653589793" xyz="0 0 0"/>
  </joint>
  <!-- Hip link -->
  <link name="LH_hip_fixed">
    <visual>
      <origin rpy="0 0 -3.141592653589793" xyz="0 0 0"/>
      <geometry>
        <mesh filename="package://anymal_c/urdf/leg/hip/hip_3_1_1_mesh_mirrored.dae" scale="1.0 1.0     1.0"/>
      </geometry>
    </visual>
    <inertial>
      <origin rpy="0 0 0" xyz="-0.048 0.008 -0.003"/>
      <mass value="0.74"/>
      <inertia ixx="0.001393106" ixy="-8.4012e-05" ixz="-2.3378e-05" iyy="0.003798579" iyz="7.1319e-05" izz="0.003897509"/>
    </inertial>
  </link>
  <!-- [rad] -->
  <!-- joint hip HFE -->
  <joint name="LH_hip_fixed_LH_HFE" type="fixed">
    <parent link="LH_hip_fixed"/>
    <child link="LH_HFE"/>
    <origin rpy="0 0 1.5707963267948966" xyz="-0.0599 0.08381 0.0"/>
  </joint>
  <!-- [m] -->
  <!-- [A] -->
  <!-- Drive link -->
  <link name="LH_HFE">
    <visual>
      <origin rpy="0 0 0" xyz="0 0 0"/>
      <geometry>
        <mesh filename="package://anymal_c/urdf/leg/drives/drive_3_0_2_mesh.dae" scale="1.0 1.0     1.0"/>
      </geometry>
    </visual>
    <collision>
      <origin rpy="0 1.5707963267948966 0" xyz="-0.07 0 0"/>
      <geometry>
        <cylinder length="0.14" radius="0.05"/>
      </geometry>
    </collision>
    <inertial>
      <origin rpy="0 0 0" xyz="-0.063 7e-05 0.00046"/>
      <mass value="2.04"/>
      <inertia ixx="0.001053013" ixy="4.527e-05" ixz="8.855e-05" iyy="0.001805509" iyz="9.909e-05" izz="0.001765827"/>
    </inertial>
  </link>
  <!-- joint Drive output -->
  <joint name="LH_HFE" type="revolute">
    <parent link="LH_HFE"/>
    <child link="LH_THIGH"/>
    <origin rpy="0 0 0" xyz="0 0 0"/>
    <axis xyz="1 0 0"/>
    <limit command_effort="80.0" current="32.0" effort="80.0" gear_velocity="7.5" lower="-9.42477796076938" upper="9.42477796076938" velocity="7.5"/>
    <dynamics damping="0.0" friction="0.0"/>
  </joint>
  <!-- Drive output link -->
  <link name="LH_THIGH">
    <inertial>
      <origin rpy="0 0 0" xyz="0 0 0"/>
      <mass value="0.001"/>
      <inertia ixx="0.000001" ixy="0.0" ixz="0.0" iyy="0.000001" iyz="0.0" izz="0.000001"/>
    </inertial>
  </link>
  <!-- [m] -->
  <!-- measured -->
  <!-- joint HFE thigh -->
  <joint name="LH_THIGH_LH_thigh_fixed" type="fixed">
    <parent link="LH_THIGH"/>
    <child link="LH_thigh_fixed"/>
    <origin rpy="0 0 -1.5707963267948966" xyz="0 0 0"/>
  </joint>
  <!-- Thigh link -->
  <link name="LH_thigh_fixed">
    <visual>
      <origin rpy="0 0 0.0" xyz="0 0 0"/>
      <geometry>
        <mesh filename="package://anymal_c/urdf/leg/thigh/thigh_3_1_1_mesh.dae" scale="1.0 1.0     1.0"/>
      </geometry>
    </visual>
    <!-- Thigh collision -->
    <collision>
      <origin rpy="1.5707963267948966 0 0" xyz="0 0.04 0"/>
      <geometry>
        <cylinder length="0.08" radius="0.065"/>
      </geometry>
    </collision>
    <collision>
      <origin rpy="0 0 0" xyz="0 0.03 -0.1413135"/>
      <geometry>
        <box size="0.07500000000000001 0.06 0.282627"/>
      </geometry>
    </collision>
    <inertial>
      <origin rpy="0 0 0" xyz="-0.0 0.018 -0.169"/>
      <mass value="1.03"/>
      <inertia ixx="0.018644469" ixy="-5.2e-08" ixz="-1.0157e-05" iyy="0.019312599" iyz="0.002520077" izz="0.002838361"/>
    </inertial>
  </link>
  <!-- [rad] -->
  <!-- joint thigh KFE -->
  <joint name="LH_thigh_fixed_LH_KFE" type="fixed">
    <parent link="LH_thigh_fixed"/>
    <child link="LH_KFE"/>
    <origin rpy="0 0 1.5707963267948966" xyz="-0.0 0.1003 -0.285"/>
  </joint>
  <!-- [m] -->
  <!-- [A] -->
  <!-- Drive link -->
  <link name="LH_KFE">
    <visual>
      <origin rpy="0 0 0" xyz="0 0 0"/>
      <geometry>
        <mesh filename="package://anymal_c/urdf/leg/drives/drive_3_0_2_mesh.dae" scale="1.0 1.0     1.0"/>
      </geometry>
    </visual>
    <collision>
      <origin rpy="0 1.5707963267948966 0" xyz="-0.07 0 0"/>
      <geometry>
        <cylinder length="0.14" radius="0.05"/>
      </geometry>
    </collision>
    <inertial>
      <origin rpy="0 0 0" xyz="-0.063 7e-05 0.00046"/>
      <mass value="2.04"/>
      <inertia ixx="0.001053013" ixy="4.527e-05" ixz="8.855e-05" iyy="0.001805509" iyz="9.909e-05" izz="0.001765827"/>
    </inertial>
  </link>
  <!-- joint Drive output -->
  <joint name="LH_KFE" type="revolute">
    <parent link="LH_KFE"/>
    <child link="LH_SHANK"/>
    <origin rpy="0 0 0" xyz="0 0 0"/>
    <axis xyz="1 0 0"/>
    <limit command_effort="80.0" current="32.0" effort="80.0" gear_velocity="7.5" lower="-9.42477796076938" upper="9.42477796076938" velocity="7.5"/>
    <dynamics damping="0.0" friction="0.0"/>
  </joint>
  <!-- Drive output link -->
  <link name="LH_SHANK">
    <inertial>
      <origin rpy="0 0 0" xyz="0 0 0"/>
      <mass value="0.001"/>
      <inertia ixx="0.000001" ixy="0.0" ixz="0.0" iyy="0.000001" iyz="0.0" izz="0.000001"/>
    </inertial>
  </link>
  <!-- [m] -->
  <!-- measured -->
  <!-- joint KFE shank -->
  <joint name="LH_shank_LH_shank_fixed" type="fixed">
    <parent link="LH_SHANK"/>
    <child link="LH_shank_fixed"/>
    <origin rpy="0 0 -1.5707963267948966" xyz="0 0 0"/>
  </joint>
  <!-- Shank link -->
  <link name="LH_shank_fixed">
    <visual>
      <origin rpy="0 0 -3.141592653589793" xyz="0 0 0"/>
      <geometry>
        <mesh filename="package://anymal_c/urdf/leg/shank/shank_3_1_1_mesh_mirrored.dae" scale="1.0 1.0     1.0"/>
      </geometry>
    </visual>
    <!-- Shank collision -->
    <collision>
      <origin rpy="1.5707963267948966 0 0" xyz="0 0.02 0"/>
      <geometry>
        <cylinder length="0.04" radius="0.06"/>
      </geometry>
    </collision>
    <collision>
      <origin rpy="1.5707963267948966 0 0" xyz="-0.057499 0.02 0"/>
      <geometry>
        <box size="0.114998 0.0675 0.04"/>
      </geometry>
    </collision>
    <inertial>
      <origin rpy="0 0 0" xyz="-0.03463 0.00688 0.00098"/>
      <mass value="0.33742"/>
      <inertia ixx="0.00032748005" ixy="-2.142561e-05" ixz="-1.33942e-05" iyy="0.00110974122" iyz="7.601e-08" izz="0.00089388521"/>
    </inertial>
  </link>
  <!-- Leg configurations: xx (knees bent inwards), xo (knees bent backwards) -->
  <!-- joint shank foot -->
  <joint name="LH_shank_fixed_LH_FOOT" type="fixed">
    <parent link="LH_shank_fixed"/>
    <child link="LH_FOOT"/>
    <origin rpy="0 0 0" xyz="-0.08795 0.01305 -0.33797"/>
  </joint>
  <!-- Foot link -->
  <link name="LH_FOOT">
    <visual>
      <origin rpy="0 0 -2.356194490192345" xyz="0 0 0"/>
      <geometry>
        <mesh filename="package://anymal_c/urdf/leg/foot/foot_3_1_1_mesh.dae" scale="1.0 1.0     1.0"/>
      </geometry>
    </visual>
    <!-- Adapter collision -->
    <collision>
      <origin rpy="0 0 0" xyz="0 0 0.168985"/>
      <geometry>
        <cylinder length="0.282504" radius="0.0175"/>
      </geometry>
    </collision>
    <!-- Foot collision -->
    <collision>
      <origin xyz="0 0 0.0225"/>
      <geometry>
        <sphere radius="0.03"/>
      </geometry>
    </collision>
    <inertial>
      <origin rpy="0 0 0" xyz="-0.00948 -0.00948 0.1468"/>
      <mass value="0.25"/>
      <inertia ixx="0.00317174097" ixy="-2.63048e-06" ixz="-6.815581e-05" iyy="0.00317174092" iyz="6.815583e-05" izz="8.319196e-05"/>
    </inertial>
  </link>
  <!-- Gazebo customization -->
  <gazebo reference="LH_FOOT">
    <kp>1000000.0</kp>
    <kd>100.0</kd>
    <mu1>0.8</mu1>
    <mu2>0.8</mu2>
  </gazebo>
  <!-- [rad] -->
  <!-- [rad] -->
  <!-- joint base HAA -->
  <joint name="base_RH_HAA" type="fixed">
    <parent link="base"/>
    <child link="RH_HAA"/>
    <origin rpy="2.6179938779914944 0 -3.141592653589793" xyz="-0.2999 -0.104 0.0"/>
  </joint>
  <!-- [m] -->
  <!-- [A] -->
  <!-- Drive link -->
  <link name="RH_HAA">
    <visual>
      <origin rpy="0 0 0" xyz="0 0 0"/>
      <geometry>
        <mesh filename="package://anymal_c/urdf/leg/drives/drive_3_0_2_mesh.dae" scale="1.0 1.0     1.0"/>
      </geometry>
    </visual>
    <inertial>
      <origin rpy="0 0 0" xyz="-0.063 7e-05 0.00046"/>
      <mass value="2.04"/>
      <inertia ixx="0.001053013" ixy="4.527e-05" ixz="8.855e-05" iyy="0.001805509" iyz="9.909e-05" izz="0.001765827"/>
    </inertial>
  </link>
  <!-- joint Drive output -->
  <joint name="RH_HAA" type="revolute">
    <parent link="RH_HAA"/>
    <child link="RH_HIP"/>
    <origin rpy="0 0 0" xyz="0 0 0"/>
    <axis xyz="-1 0 0"/>
    <limit command_effort="80.0" current="32.0" effort="80.0" gear_velocity="7.5" lower="-0.49" upper="0.72" velocity="7.5"/>
    <dynamics damping="0.0" friction="0.0"/>
  </joint>
  <!-- Drive output link -->
  <link name="RH_HIP">
    <inertial>
      <origin rpy="0 0 0" xyz="0 0 0"/>
      <mass value="0.001"/>
      <inertia ixx="0.000001" ixy="0.0" ixz="0.0" iyy="0.000001" iyz="0.0" izz="0.000001"/>
    </inertial>
  </link>
  <!-- [kg * m^2] -->
  <!-- joint HAA hip -->
  <joint name="RH_HIP_RH_hip_fixed" type="fixed">
    <parent link="RH_HIP"/>
    <child link="RH_hip_fixed"/>
    <origin rpy="2.6179938779914944 0 -3.141592653589793" xyz="0 0 0"/>
  </joint>
  <!-- Hip link -->
  <link name="RH_hip_fixed">
    <visual>
      <origin rpy="0 0 -3.141592653589793" xyz="0 0 0"/>
      <geometry>
        <mesh filename="package://anymal_c/urdf/leg/hip/hip_3_1_1_mesh.dae" scale="1.0 1.0     1.0"/>
      </geometry>
    </visual>
    <inertial>
      <origin rpy="0 0 0" xyz="-0.048 -0.008 -0.003"/>
      <mass value="0.74"/>
      <inertia ixx="0.001393106" ixy="8.4012e-05" ixz="-2.3378e-05" iyy="0.003798579" iyz="-7.1319e-05" izz="0.003897509"/>
    </inertial>
  </link>
  <!-- [rad] -->
  <!-- joint hip HFE -->
  <joint name="RH_hip_fixed_RH_HFE" type="fixed">
    <parent link="RH_hip_fixed"/>
    <child link="RH_HFE"/>
    <origin rpy="0 0 -1.5707963267948966" xyz="-0.0599 -0.08381 0.0"/>
  </joint>
  <!-- [m] -->
  <!-- [A] -->
  <!-- Drive link -->
  <link name="RH_HFE">
    <visual>
      <origin rpy="0 0 0" xyz="0 0 0"/>
      <geometry>
        <mesh filename="package://anymal_c/urdf/leg/drives/drive_3_0_2_mesh.dae" scale="1.0 1.0     1.0"/>
      </geometry>
    </visual>
    <collision>
      <origin rpy="0 1.5707963267948966 0" xyz="-0.07 0 0"/>
      <geometry>
        <cylinder length="0.14" radius="0.05"/>
      </geometry>
    </collision>
    <inertial>
      <origin rpy="0 0 0" xyz="-0.063 7e-05 0.00046"/>
      <mass value="2.04"/>
      <inertia ixx="0.001053013" ixy="4.527e-05" ixz="8.855e-05" iyy="0.001805509" iyz="9.909e-05" izz="0.001765827"/>
    </inertial>
  </link>
  <!-- joint Drive output -->
  <joint name="RH_HFE" type="revolute">
    <parent link="RH_HFE"/>
    <child link="RH_THIGH"/>
    <origin rpy="0 0 0" xyz="0 0 0"/>
    <axis xyz="-1 0 0"/>
    <limit command_effort="80.0" current="32.0" effort="80.0" gear_velocity="7.5" lower="-9.42477796076938" upper="9.42477796076938" velocity="7.5"/>
    <dynamics damping="0.0" friction="0.0"/>
  </joint>
  <!-- Drive output link -->
  <link name="RH_THIGH">
    <inertial>
      <origin rpy="0 0 0" xyz="0 0 0"/>
      <mass value="0.001"/>
      <inertia ixx="0.000001" ixy="0.0" ixz="0.0" iyy="0.000001" iyz="0.0" izz="0.000001"/>
    </inertial>
  </link>
  <!-- [m] -->
  <!-- measured -->
  <!-- joint HFE thigh -->
  <joint name="RH_THIGH_RH_thigh_fixed" type="fixed">
    <parent link="RH_THIGH"/>
    <child link="RH_thigh_fixed"/>
    <origin rpy="0 0 1.5707963267948966" xyz="0 0 0"/>
  </joint>
  <!-- Thigh link -->
  <link name="RH_thigh_fixed">
    <visual>
      <origin rpy="0 0 -3.141592653589793" xyz="0 0 0"/>
      <geometry>
        <mesh filename="package://anymal_c/urdf/leg/thigh/thigh_3_1_1_mesh.dae" scale="1.0 1.0     1.0"/>
      </geometry>
    </visual>
    <!-- Thigh collision -->
    <collision>
      <origin rpy="1.5707963267948966 0 0" xyz="0 -0.04 0"/>
      <geometry>
        <cylinder length="0.08" radius="0.065"/>
      </geometry>
    </collision>
    <collision>
      <origin rpy="0 0 0" xyz="0 -0.03 -0.1413135"/>
      <geometry>
        <box size="0.07500000000000001 0.06 0.282627"/>
      </geometry>
    </collision>
    <inertial>
      <origin rpy="0 0 0" xyz="-0.0 -0.018 -0.169"/>
      <mass value="1.03"/>
      <inertia ixx="0.018644469" ixy="5.2e-08" ixz="-1.0157e-05" iyy="0.019312599" iyz="-0.002520077" izz="0.002838361"/>
    </inertial>
  </link>
  <!-- [rad] -->
  <!-- joint thigh KFE -->
  <joint name="RH_thigh_fixed_RH_KFE" type="fixed">
    <parent link="RH_thigh_fixed"/>
    <child link="RH_KFE"/>
    <origin rpy="0 0 -1.5707963267948966" xyz="-0.0 -0.1003 -0.285"/>
  </joint>
  <!-- [m] -->
  <!-- [A] -->
  <!-- Drive link -->
  <link name="RH_KFE">
    <visual>
      <origin rpy="0 0 0" xyz="0 0 0"/>
      <geometry>
        <mesh filename="package://anymal_c/urdf/leg/drives/drive_3_0_2_mesh.dae" scale="1.0 1.0     1.0"/>
      </geometry>
    </visual>
    <collision>
      <origin rpy="0 1.5707963267948966 0" xyz="-0.07 0 0"/>
      <geometry>
        <cylinder length="0.14" radius="0.05"/>
      </geometry>
    </collision>
    <inertial>
      <origin rpy="0 0 0" xyz="-0.063 7e-05 0.00046"/>
      <mass value="2.04"/>
      <inertia ixx="0.001053013" ixy="4.527e-05" ixz="8.855e-05" iyy="0.001805509" iyz="9.909e-05" izz="0.001765827"/>
    </inertial>
  </link>
  <!-- joint Drive output -->
  <joint name="RH_KFE" type="revolute">
    <parent link="RH_KFE"/>
    <child link="RH_SHANK"/>
    <origin rpy="0 0 0" xyz="0 0 0"/>
    <axis xyz="-1 0 0"/>
    <limit command_effort="80.0" current="32.0" effort="80.0" gear_velocity="7.5" lower="-9.42477796076938" upper="9.42477796076938" velocity="7.5"/>
    <dynamics damping="0.0" friction="0.0"/>
  </joint>
  <!-- Drive output link -->
  <link name="RH_SHANK">
    <inertial>
      <origin rpy="0 0 0" xyz="0 0 0"/>
      <mass value="0.001"/>
      <inertia ixx="0.000001" ixy="0.0" ixz="0.0" iyy="0.000001" iyz="0.0" izz="0.000001"/>
    </inertial>
  </link>
  <!-- [m] -->
  <!-- measured -->
  <!-- joint KFE shank -->
  <joint name="RH_shank_RH_shank_fixed" type="fixed">
    <parent link="RH_SHANK"/>
    <child link="RH_shank_fixed"/>
    <origin rpy="0 0 1.5707963267948966" xyz="0 0 0"/>
  </joint>
  <!-- Shank link -->
  <link name="RH_shank_fixed">
    <visual>
      <origin rpy="0 0 -3.141592653589793" xyz="0 0 0"/>
      <geometry>
        <mesh filename="package://anymal_c/urdf/leg/shank/shank_3_1_1_mesh.dae" scale="1.0 1.0     1.0"/>
      </geometry>
    </visual>
    <!-- Shank collision -->
    <collision>
      <origin rpy="1.5707963267948966 0 0" xyz="0 -0.02 0"/>
      <geometry>
        <cylinder length="0.04" radius="0.06"/>
      </geometry>
    </collision>
    <collision>
      <origin rpy="1.5707963267948966 0 0" xyz="-0.057499 -0.02 0"/>
      <geometry>
        <box size="0.114998 0.0675 0.04"/>
      </geometry>
    </collision>
    <inertial>
      <origin rpy="0 0 0" xyz="-0.03463 -0.00688 0.00098"/>
      <mass value="0.33742"/>
      <inertia ixx="0.00032748005" ixy="2.142561e-05" ixz="-1.33942e-05" iyy="0.00110974122" iyz="-7.601e-08" izz="0.00089388521"/>
    </inertial>
  </link>
  <!-- Leg configurations: xx (knees bent inwards), xo (knees bent backwards) -->
  <!-- joint shank foot -->
  <joint name="RH_shank_fixed_RH_FOOT" type="fixed">
    <parent link="RH_shank_fixed"/>
    <child link="RH_FOOT"/>
    <origin rpy="0 0 0" xyz="-0.08795 -0.01305 -0.33797"/>
  </joint>
  <!-- Foot link -->
  <link name="RH_FOOT">
    <visual>
      <origin rpy="0 0 -3.9269908169872414" xyz="0 0 0"/>
      <geometry>
        <mesh filename="package://anymal_c/urdf/leg/foot/foot_3_1_1_mesh.dae" scale="1.0 1.0     1.0"/>
      </geometry>
    </visual>
    <!-- Adapter collision -->
    <collision>
      <origin rpy="0 0 0" xyz="0 0 0.168985"/>
      <geometry>
        <cylinder length="0.282504" radius="0.0175"/>
      </geometry>
    </collision>
    <!-- Foot collision -->
    <collision>
      <origin xyz="0 0 0.0225"/>
      <geometry>
        <sphere radius="0.03"/>
      </geometry>
    </collision>
    <inertial>
      <origin rpy="0 0 0" xyz="-0.00948 0.00948 0.1468"/>
      <mass value="0.25"/>
      <inertia ixx="0.00317174097" ixy="2.63048e-06" ixz="-6.815581e-05" iyy="0.00317174092" iyz="-6.815583e-05" izz="8.319196e-05"/>
    </inertial>
  </link>
  <!-- Gazebo customization -->
  <gazebo reference="RH_FOOT">
    <kp>1000000.0</kp>
    <kd>100.0</kd>
    <mu1>0.8</mu1>
    <mu2>0.8</mu2>
  </gazebo>
</robot>

