<?xml version="1.0" encoding="utf-8"?>

<robot name="dummy">

  <link name="world"/>

  <joint name="world_joint" type="fixed">
    <parent link="world"/>
    <child link="base"/>
    <origin xyz="0 0 0" rqy="0 0 0"/>
  </joint>

  <link name="base">
    <visual>
      <origin xyz="0 0 0.15" rpy="0 0 0"/>
      <geometry>
        <box size="1.0 0.5 0.3"/>
      </geometry>
    </visual>
    
    <collision>
      <origin xyz="0 0 0.15" rpy="0 0 0"/>
      <geometry>
        <box size="1.0 0.5 0.3"/>
      </geometry>
    </collision>

    <collision>
      <origin xyz="-0.3 0 0.4" rpy="0 0 0"/>
      <geometry>
        <box size="0.2 0.2 0.2"/>
      </geometry>
    </collision>
  </link>

  <joint name="SH_ROT" type="revolute">
    <parent link="base"/>
    <child link="shoulder"/>
    <origin xyz="0.4 0 0.3" rpy="0 0 0"/>
    <axis xyz="0 0 1"/>
    <limit effort="100" lower="-1.57" upper="1.57" velocity="10"/>
  </joint>

  <link name="shoulder">
    <visual>
      <origin xyz="0 0 0.05" rpy="0 0 0"/>
      <geometry>
        <cylinder radius="0.1" length="0.1"/>
      </geometry>
    </visual>
    
    <collision>
      <origin xyz="0 0 0.05" rpy="0 0 0"/>
      <geometry>
        <cylinder radius="0.1" length="0.1"/>
      </geometry>
    </collision>
  </link>

  <joint name="SH_FLE" type="revolute">
    <parent link="shoulder"/>
    <child link="upperarm"/>
    <origin xyz="0 0 0.1" rpy="0 0 0"/>
    <axis xyz="0 1 0"/>
    <limit effort="100" lower="-1.57" upper="1.57" velocity="10"/>
  </joint>

  <link name="upperarm">
    <visual>
      <origin xyz="0 0 0.2" rpy="0 0 0"/>
      <geometry>
        <cylinder radius="0.075" length="0.5"/>
      </geometry>
    </visual>
    
    <collision>
      <origin xyz="0 0 0.2" rpy="0 0 0"/>
      <geometry>
        <cylinder radius="0.05" length="0.5"/>
      </geometry>
    </collision>
  </link>

  <joint name="EL_FLE" type="revolute">
    <parent link="upperarm"/>
    <child link="forearm"/>
    <origin xyz="0 0 0.5" rpy="0 0 0"/>
    <axis xyz="0 1 0"/>
    <limit effort="100" lower="-1.57" upper="3.14" velocity="10"/>
  </joint>

  <link name="forearm">
    <visual>
      <origin xyz="0 0 0.2" rpy="0 0 0"/>
      <geometry>
        <box size="0.1 0.1 0.5"/>
      </geometry>
    </visual>
    
    <collision>
      <origin xyz="0 0 0.2" rpy="0 0 0"/>
      <geometry>
        <box size="0.1 0.1 0.5"/>
      </geometry>
    </collision>
  </link>
</robot>